Workbook

Sheet Intro
A19: STEPS:
A20: 1) enter financial data on the Financial Statements sheet,
A21: 2) examine the Ratio Analysis and Cash Flow Analysis,
A22: 3) enter forecasts on the Forecasting Assumptions sheet to predict the future Financial Statements,
A23: 4) enter cost of capital assumptions on the Valuation Parameters Sheet to determine the company's value,
A24: 5) evaluate the details of the resulting valuation using either the Residual Income or Discounted Cash Flow Valuations.

Sheet Financial Statements
A1: Financial Statements | B1: ($000s) | C1: Data can be entered manually in financial statements or as a block cut-and-paste from the Case Data Sheet to the Raw Data Input section below.
C3: Jump to Raw Data Input
A4: Company Name, Ticker and SIC | B4: =B82 -> DOLLAR TREE 2021 | D4: =D82 -> DLTR | E4: =F82 -> 5331 | F4: =IF(D4="","",HYPERLINK(CONCATENATE("http://www.sec.gov/cgi-bin/browse-edgar?type=10-K&action=getcompany&CIK=",D4),"Link to Form 10-Ks")) -> Link to Form 10-Ks
A5: Common Shares Outstanding | B5: =B83 -> 225100.2 | C5: (in 000s at most recent fiscal year end) | F5: Link to Industry Comps
A6: ="Estimated Price/Share="&DOLLAR('Valuation Parameters'!B24) -> Estimated Price/Share=£105.41
B7: Actual | C7: Actual | D7: Actual | E7: Actual | F7: Actual | G7: Forecast | H7: Forecast | I7: Forecast | J7: Forecast | K7: Forecast | L7: Forecast | M7: Forecast | N7: Forecast | O7: Forecast | P7: Forecast | Q7: Forecast | R7: Forecast
A8: Fiscal Year End (YYYY-MM-DD) | B8: =B84 -> 41669 | C8: =C84 -> 42034 | D8: =D84 -> 42399 | E8: =E84 -> 42765 | F8: =F84 -> 43130 | G8: =DATE(YEAR(F8)+1,MONTH(F8),DAY(F8)) -> 43495 | H8: =DATE(YEAR(G8)+1,MONTH(G8),DAY(G8)) -> 43860 | I8: =DATE(YEAR(H8)+1,MONTH(H8),DAY(H8)) -> 44226 | J8: =DATE(YEAR(I8)+1,MONTH(I8),DAY(I8)) -> 44591 | K8: =DATE(YEAR(J8)+1,MONTH(J8),DAY(J8)) -> 44956 | L8: =DATE(YEAR(K8)+1,MONTH(K8),DAY(K8)) -> 45321 | M8: =DATE(YEAR(L8)+1,MONTH(L8),DAY(L8)) -> 45687 | N8: =DATE(YEAR(M8)+1,MONTH(M8),DAY(M8)) -> 46052 | ... R8: =DATE(YEAR(Q8)+1,MONTH(Q8),DAY(Q8)) -> 47513
A10: Income Statement
A12: Sales (Net) | B12: =B85 -> 22245500 | C12: =C85 -> 22823300 | D12: =D85 -> 23610800 | E12: =E85 -> 25509300 | F12: =F85 -> 26321200 | G12: =F12*(1+'Forecasting Assumptions'!G14) -> 27154568 | H12: =G12*(1+'Forecasting Assumptions'!H14) -> 28009809 | I12: =H12*(1+'Forecasting Assumptions'!I14) -> 28887333 | J12: =I12*(1+'Forecasting Assumptions'!J14) -> 29787550 | K12: =J12*(1+'Forecasting Assumptions'!K14) -> 30710871 | L12: =K12*(1+'Forecasting Assumptions'!L14) -> 31657710 | M12: =L12*(1+'Forecasting Assumptions'!M14) -> 32628480 | N12: =M12*(1+'Forecasting Assumptions'!N14) -> 33623598 | ... R12: =Q12*(1+'Forecasting Assumptions'!R14) -> 37861971
A13: Cost of Goods Sold | B13: =B86 -> -15223600 | C13: =C86 -> -15875800 | D13: =D86 -> -16570100 | E13: =E86 -> -17721900 | F13: =F86 -> -18595300 | G13: =-G12*'Forecasting Assumptions'!G15 -> -19184054 | H13: =-H12*'Forecasting Assumptions'!H15 -> -19788262 | I13: =-I12*'Forecasting Assumptions'!I15 -> -20408212 | J13: =-J12*'Forecasting Assumptions'!J15 -> -21044194 | K13: =-K12*'Forecasting Assumptions'!K15 -> -21696498 | L13: =-L12*'Forecasting Assumptions'!L15 -> -22365417 | M13: =-M12*'Forecasting Assumptions'!M15 -> -23051243 | N13: =-N12*'Forecasting Assumptions'!N15 -> -23754270 | ... R13: =-R12*'Forecasting Assumptions'!R15 -> -26748579
A14: Gross Profit | B14: =B12+B13 -> 7021900 | C14: =C12+C13 -> 6947500 | D14: =D12+D13 -> 7040700 | E14: =E12+E13 -> 7787400 | F14: =F12+F13 -> 7725900 | G14: =G12+G13 -> 7970513.3 | H14: =H12+H13 -> 8221547.1 | I14: =I12+I13 -> 8479121.4 | ... R14: =R12+R13 -> 11113392
A15: R&D Expense | B15: =B87 -> 0 | C15: =C87 -> 0 | D15: =D87 -> 0 | E15: =E87 -> 0 | F15: =F87 -> 0 | G15: =-G12*'Forecasting Assumptions'!G16 -> 0 | H15: =-H12*'Forecasting Assumptions'!H16 -> 0 | I15: =-I12*'Forecasting Assumptions'!I16 -> 0 | J15: =-J12*'Forecasting Assumptions'!J16 -> 0 | K15: =-K12*'Forecasting Assumptions'!K16 -> 0 | L15: =-L12*'Forecasting Assumptions'!L16 -> 0 | M15: =-M12*'Forecasting Assumptions'!M16 -> 0 | N15: =-N12*'Forecasting Assumptions'!N16 -> 0 | ... R15: =-R12*'Forecasting Assumptions'!R16 -> 0
A16: SG&A Expense | B16: =B88 -> -4953600 | C16: =C88 -> -7887000 | D16: =D88 -> -5778500 | E16: =E88 -> -5899500 | F16: =F88 -> -5914500 | G16: =-G12*'Forecasting Assumptions'!G17 -> -6101761.7 | H16: =-H12*'Forecasting Assumptions'!H17 -> -6293938.6 | I16: =-I12*'Forecasting Assumptions'!I17 -> -6491122.5 | J16: =-J12*'Forecasting Assumptions'!J17 -> -6693405.5 | K16: =-K12*'Forecasting Assumptions'!K17 -> -6900880.2 | L16: =-L12*'Forecasting Assumptions'!L17 -> -7113639.3 | M16: =-M12*'Forecasting Assumptions'!M17 -> -7331776.1 | N16: =-N12*'Forecasting Assumptions'!N17 -> -7555383.9 | ... R16: =-R12*'Forecasting Assumptions'!R17 -> -8507766.6
A17: EBITDA | B17: =B14+B15+B16 -> 2068300 | C17: =C14+C15+C16 -> -939500 | D17: =D14+D15+D16 -> 1262200 | E17: =E14+E15+E16 -> 1887900 | F17: =F14+F15+F16 -> 1811400 | G17: =G14+G15+G16 -> 1868751.6 | H17: =H14+H15+H16 -> 1927608.5 | I17: =I14+I15+I16 -> 1987998.9 | ... R17: =R14+R15+R16 -> 2605624.9
A18: Depreciation & Amortization | B18: =B89 -> -69200 | C18: =C89 -> 0 | D18: =D89 -> 0 | E18: =E89 -> 0 | F18: =F89 -> 0 | G18: =-((F38+G38+F40+G40)/2)*'Forecasting Assumptions'!G18 -> 0 | H18: =-((G38+H38+G40+H40)/2)*'Forecasting Assumptions'!H18 -> 0 | I18: =-((H38+I38+H40+I40)/2)*'Forecasting Assumptions'!I18 -> 0 | J18: =-((I38+J38+I40+J40)/2)*'Forecasting Assumptions'!J18 -> 0 | K18: =-((J38+K38+J40+K40)/2)*'Forecasting Assumptions'!K18 -> 0 | L18: =-((K38+L38+K40+L40)/2)*'Forecasting Assumptions'!L18 -> 0 | M18: =-((L38+M38+L40+M40)/2)*'Forecasting Assumptions'!M18 -> 0 | N18: =-((M38+N38+M40+N40)/2)*'Forecasting Assumptions'!N18 -> 0 | ... R18: =-((Q38+R38+Q40+R40)/2)*'Forecasting Assumptions'!R18 -> 0
A19: EBIT | B19: =B17+B18 -> 1999100 | C19: =C17+C18 -> -939500 | D19: =D17+D18 -> 1262200 | E19: =E17+E18 -> 1887900 | F19: =F17+F18 -> 1811400 | G19: =G17+G18 -> 1868751.6 | H19: =H17+H18 -> 1927608.5 | I19: =I17+I18 -> 1987998.9 | ... R19: =R17+R18 -> 2605624.9
A20: Net Interest Expense | B20: =B90 -> -301800 | C20: =C90 -> -370000 | D20: =D90 -> -162100 | E20: =E90 -> -147300 | F20: =F90 -> -178900 | G20: =-((F44+G44+F49+G49)/2)*'Forecasting Assumptions'!G19 -> -186951.66 | H20: =-((G44+H44+G49+H49)/2)*'Forecasting Assumptions'!H19 -> -192855.05 | I20: =-((H44+I44+H49+I49)/2)*'Forecasting Assumptions'!I19 -> -198912.82 | J20: =-((I44+J44+I49+J49)/2)*'Forecasting Assumptions'!J19 -> -205127.81 | K20: =-((J44+K44+J49+K49)/2)*'Forecasting Assumptions'!K19 -> -211502.91 | L20: =-((K44+L44+K49+L49)/2)*'Forecasting Assumptions'!L19 -> -218041 | M20: =-((L44+M44+L49+M49)/2)*'Forecasting Assumptions'!M19 -> -224744.98 | N20: =-((M44+N44+M49+N49)/2)*'Forecasting Assumptions'!N19 -> -231617.74 | ... R20: =-((Q44+R44+Q49+R49)/2)*'Forecasting Assumptions'!R19 -> -260876.13
A21: Non-Operating Income (Loss) | B21: =B91 -> 6700 | C21: =C91 -> 500 | D21: =D91 -> -1400 | E21: =E91 -> -800 | F21: =F91 -> -300 | G21: =G12*'Forecasting Assumptions'!G20 -> -309.49844 | H21: =H12*'Forecasting Assumptions'!H20 -> -319.24619 | I21: =I12*'Forecasting Assumptions'!I20 -> -329.24791 | J21: =J12*'Forecasting Assumptions'!J20 -> -339.50827 | K21: =K12*'Forecasting Assumptions'!K20 -> -350.03196 | L21: =L12*'Forecasting Assumptions'!L20 -> -360.82371 | M21: =M12*'Forecasting Assumptions'!M20 -> -371.88821 | N21: =N12*'Forecasting Assumptions'!N20 -> -383.23022 | ... R21: =R12*'Forecasting Assumptions'!R20 -> -431.53774
A22: EBT | B22: =B19+B20+B21 -> 1704000 | C22: =C19+C20+C21 -> -1309000 | D22: =D19+D20+D21 -> 1098700 | E22: =E19+E20+E21 -> 1739800 | F22: =F19+F20+F21 -> 1632200 | G22: =G19+G20+G21 -> 1681490.4 | H22: =H19+H20+H21 -> 1734434.2 | I22: =I19+I20+I21 -> 1788756.8 | ... R22: =R19+R20+R21 -> 2344317.2
A23: Income Taxes | B23: =B92 -> 10300 | C23: =C92 -> -281800 | D23: =D92 -> -271700 | E23: =E92 -> -397900 | F23: =F92 -> -304300 | G23: =-G22*'Forecasting Assumptions'!G21 -> -313489.48 | H23: =-H22*'Forecasting Assumptions'!H21 -> -323360.08 | I23: =-I22*'Forecasting Assumptions'!I21 -> -333487.74 | J23: =-J22*'Forecasting Assumptions'!J21 -> -343877.2 | K23: =-K22*'Forecasting Assumptions'!K21 -> -354533.19 | L23: =-L22*'Forecasting Assumptions'!L21 -> -365460.48 | M23: =-M22*'Forecasting Assumptions'!M21 -> -376663.85 | N23: =-N22*'Forecasting Assumptions'!N21 -> -388148.08 | ... R23: =-R22*'Forecasting Assumptions'!R21 -> -437063.92
A24: Other Income (Loss) | B24: =B94 -> 0 | C24: =C94 -> 0 | D24: =D94 -> 0 | E24: =E94 -> 0 | F24: =F94 -> 0 | G24: =G12*'Forecasting Assumptions'!G23 -> 0 | H24: =H12*'Forecasting Assumptions'!H23 -> 0 | I24: =I12*'Forecasting Assumptions'!I23 -> 0 | J24: =J12*'Forecasting Assumptions'!J23 -> 0 | K24: =K12*'Forecasting Assumptions'!K23 -> 0 | L24: =L12*'Forecasting Assumptions'!L23 -> 0 | M24: =M12*'Forecasting Assumptions'!M23 -> 0 | N24: =N12*'Forecasting Assumptions'!N23 -> 0 | ... R24: =R12*'Forecasting Assumptions'!R23 -> 0
A25: Net Income Before Ext. Items | B25: =B22+B23+B24 -> 1714300 | C25: =C22+C23+C24 -> -1590800 | D25: =D22+D23+D24 -> 827000 | E25: =E22+E23+E24 -> 1341900 | F25: =F22+F23+F24 -> 1327900 | G25: =G22+G23+G24 -> 1368000.9 | H25: =H22+H23+H24 -> 1411074.1 | I25: =I22+I23+I24 -> 1455269.1 | ... R25: =R22+R23+R24 -> 1907253.3
A26: Ext. Items & Disc. Ops. | B26: =B95 -> 0 | C26: =C95 -> 0 | D26: =D95 -> 0 | E26: =E95 -> 0 | F26: =F95 -> 0 | G26: =G12*'Forecasting Assumptions'!G24 -> 0 | H26: =H12*'Forecasting Assumptions'!H24 -> 0 | I26: =I12*'Forecasting Assumptions'!I24 -> 0 | J26: =J12*'Forecasting Assumptions'!J24 -> 0 | K26: =K12*'Forecasting Assumptions'!K24 -> 0 | L26: =L12*'Forecasting Assumptions'!L24 -> 0 | M26: =M12*'Forecasting Assumptions'!M24 -> 0 | N26: =N12*'Forecasting Assumptions'!N24 -> 0 | ... R26: =R12*'Forecasting Assumptions'!R24 -> 0
A27: Noncontrolling Interest in Earnings | B27: =B93 -> 0 | C27: =C93 -> 0 | D27: =D93 -> 0 | E27: =E93 -> 0 | F27: =F93 -> 0 | G27: =-(G22+G23)*'Forecasting Assumptions'!G22 -> 0 | H27: =-(H22+H23)*'Forecasting Assumptions'!H22 -> 0 | I27: =-(I22+I23)*'Forecasting Assumptions'!I22 -> 0 | J27: =-(J22+J23)*'Forecasting Assumptions'!J22 -> 0 | K27: =-(K22+K23)*'Forecasting Assumptions'!K22 -> 0 | L27: =-(L22+L23)*'Forecasting Assumptions'!L22 -> 0 | M27: =-(M22+M23)*'Forecasting Assumptions'!M22 -> 0 | N27: =-(N22+N23)*'Forecasting Assumptions'!N22 -> 0 | ... R27: =-(R22+R23)*'Forecasting Assumptions'!R22 -> 0
A28: Preferred Dividends | B28: =B96 -> 0 | C28: =C96 -> 0 | D28: =D96 -> 0 | E28: =E96 -> 0 | F28: =F96 -> 0 | G28: =-((G54+F54)/2)*'Forecasting Assumptions'!G25 -> 0 | H28: =-((H54+G54)/2)*'Forecasting Assumptions'!H25 -> 0 | I28: =-((I54+H54)/2)*'Forecasting Assumptions'!I25 -> 0 | J28: =-((J54+I54)/2)*'Forecasting Assumptions'!J25 -> 0 | K28: =-((K54+J54)/2)*'Forecasting Assumptions'!K25 -> 0 | L28: =-((L54+K54)/2)*'Forecasting Assumptions'!L25 -> 0 | M28: =-((M54+L54)/2)*'Forecasting Assumptions'!M25 -> 0 | N28: =-((N54+M54)/2)*'Forecasting Assumptions'!N25 -> 0 | ... R28: =-((R54+Q54)/2)*'Forecasting Assumptions'!R25 -> 0
A29: Net Income (available to common) | B29: =B25+B26+B27+B28 -> 1714300 | C29: =C25+C26+C27+C28 -> -1590800 | D29: =D25+D26+D27+D28 -> 827000 | E29: =E25+E26+E27+E28 -> 1341900 | F29: =F25+F26+F27+F28 -> 1327900 | G29: =G25+G26+G27+G28 -> 1368000.9 | H29: =H25+H26+H27+H28 -> 1411074.1 | I29: =I25+I26+I27+I28 -> 1455269.1 | ... R29: =R25+R26+R27+R28 -> 1907253.3
B30: =IF(B13>0,"Error! -Exp?",IF(B15>0,"Error! -Exp?",IF(B16>0,"Error! -Exp?","")))
A31: Balance Sheet
A33: Operating Cash and Market. Sec. | B33: =B97 -> 1097800 | C33: =C97 -> 446700 | D33: =D97 -> 586000 | E33: =E97 -> 1463600 | F33: =F97 -> 1038300 | G33: =G12*'Forecasting Assumptions'!G29 -> 1071174.1 | H33: =H12*'Forecasting Assumptions'!H29 -> 1104911.1 | I33: =I12*'Forecasting Assumptions'!I29 -> 1139527 | J33: =J12*'Forecasting Assumptions'!J29 -> 1175038.1 | K33: =K12*'Forecasting Assumptions'!K29 -> 1211460.6 | L33: =L12*'Forecasting Assumptions'!L29 -> 1248810.8 | M33: =M12*'Forecasting Assumptions'!M29 -> 1287105.1 | N33: =N12*'Forecasting Assumptions'!N29 -> 1326359.8 | ... R33: =R12*'Forecasting Assumptions'!R29 -> 1493552.1
A34: Receivables | B34: =B98 -> 0 | C34: =C98 -> 100900 | D34: =D98 -> 0 | E34: =E98 -> 0 | F34: =F98 -> 0 | G34: =G12*'Forecasting Assumptions'!G30 -> 0 | H34: =H12*'Forecasting Assumptions'!H30 -> 0 | I34: =I12*'Forecasting Assumptions'!I30 -> 0 | J34: =J12*'Forecasting Assumptions'!J30 -> 0 | K34: =K12*'Forecasting Assumptions'!K30 -> 0 | L34: =L12*'Forecasting Assumptions'!L30 -> 0 | M34: =M12*'Forecasting Assumptions'!M30 -> 0 | N34: =N12*'Forecasting Assumptions'!N30 -> 0 | ... R34: =R12*'Forecasting Assumptions'!R30 -> 0
A35: Inventories | B35: =B99 -> 3169300 | C35: =C99 -> 3536000 | D35: =D99 -> 3522000 | E35: =E99 -> 3427000 | F35: =F99 -> 4367300 | G35: =-G13*'Forecasting Assumptions'!G31 -> 4505575.1 | H35: =-H13*'Forecasting Assumptions'!H31 -> 4647479.6 | I35: =-I13*'Forecasting Assumptions'!I31 -> 4793081.3 | J35: =-J13*'Forecasting Assumptions'!J31 -> 4942448.2 | K35: =-K13*'Forecasting Assumptions'!K31 -> 5095648.7 | L35: =-L13*'Forecasting Assumptions'!L31 -> 5252751.2 | M35: =-M13*'Forecasting Assumptions'!M31 -> 5413824.7 | N35: =-N13*'Forecasting Assumptions'!N31 -> 5578937.9 | ... R35: =-R13*'Forecasting Assumptions'!R31 -> 6282182.6
A36: Other Current Assets | B36: =B100 -> 309200 | C36: =C100 -> 209700 | D36: =D100 -> 161400 | E36: =E100 -> 160200 | F36: =F100 -> 203600 | G36: =G12*'Forecasting Assumptions'!G32 -> 210046.27 | H36: =H12*'Forecasting Assumptions'!H32 -> 216661.75 | I36: =I12*'Forecasting Assumptions'!I32 -> 223449.58 | J36: =J12*'Forecasting Assumptions'!J32 -> 230412.94 | K36: =K12*'Forecasting Assumptions'!K32 -> 237555.03 | L36: =L12*'Forecasting Assumptions'!L32 -> 244879.02 | M36: =M12*'Forecasting Assumptions'!M32 -> 252388.13 | N36: =N12*'Forecasting Assumptions'!N32 -> 260085.58 | ... R36: =R12*'Forecasting Assumptions'!R32 -> 292870.28
A37: Total Current Assets | B37: =SUM(B33:B36) -> 4576300 | C37: =SUM(C33:C36) -> 4293300 | D37: =SUM(D33:D36) -> 4269400 | E37: =SUM(E33:E36) -> 5050800 | F37: =SUM(F33:F36) -> 5609200 | G37: =SUM(G33:G36) -> 5786795.5 | H37: =SUM(H33:H36) -> 5969052.4 | I37: =SUM(I33:I36) -> 6156057.9 | ... R37: =SUM(R33:R36) -> 8068605.1
A38: PP&E (Net) | B38: =B101 -> 3200700 | C38: =C101 -> 3445300 | D38: =D101 -> 3881800 | E38: =E101 -> 4116300 | F38: =F101 -> 4477300 | G38: =G12*'Forecasting Assumptions'!G37 -> 4619057.9 | H38: =H12*'Forecasting Assumptions'!H37 -> 4764536.5 | I38: =I12*'Forecasting Assumptions'!I37 -> 4913805.5 | J38: =J12*'Forecasting Assumptions'!J37 -> 5066934.6 | K38: =K12*'Forecasting Assumptions'!K37 -> 5223993.7 | L38: =L12*'Forecasting Assumptions'!L37 -> 5385053.2 | M38: =M12*'Forecasting Assumptions'!M37 -> 5550183.7 | N38: =N12*'Forecasting Assumptions'!N37 -> 5719455.6 | ... R38: =R12*'Forecasting Assumptions'!R37 -> 6440413.2
A39: Investments | B39: =B102 -> 0 | C39: =C102 -> 0 | D39: =D102 -> 0 | E39: =E102 -> 0 | F39: =F102 -> 0 | G39: =G12*'Forecasting Assumptions'!G38 -> 0 | H39: =H12*'Forecasting Assumptions'!H38 -> 0 | I39: =I12*'Forecasting Assumptions'!I38 -> 0 | J39: =J12*'Forecasting Assumptions'!J38 -> 0 | K39: =K12*'Forecasting Assumptions'!K38 -> 0 | L39: =L12*'Forecasting Assumptions'!L38 -> 0 | M39: =M12*'Forecasting Assumptions'!M38 -> 0 | N39: =N12*'Forecasting Assumptions'!N38 -> 0 | ... R39: =R12*'Forecasting Assumptions'!R38 -> 0
A40: Intangibles | B40: =B103 -> 5025200 | C40: =C103 -> 5685300 | D40: =D103 -> 5083300 | E40: =E103 -> 5084400 | F40: =F103 -> 5084400 | G40: =G12*'Forecasting Assumptions'!G39 -> 5245379.5 | H40: =H12*'Forecasting Assumptions'!H39 -> 5410584.4 | I40: =I12*'Forecasting Assumptions'!I39 -> 5580093.5 | J40: =J12*'Forecasting Assumptions'!J39 -> 5753986.1 | K40: =K12*'Forecasting Assumptions'!K39 -> 5932341.7 | L40: =L12*'Forecasting Assumptions'!L39 -> 6115240.2 | M40: =M12*'Forecasting Assumptions'!M39 -> 6302761.5 | N40: =N12*'Forecasting Assumptions'!N39 -> 6494985.8 | ... R40: =R12*'Forecasting Assumptions'!R39 -> 7313701.7
A41: Other Assets | B41: =B104 -> 3530600 | C41: =C104 -> 77300 | D41: =D104 -> 6340100 | E41: =E104 -> 6444500 | F41: =F104 -> 6550900 | G41: =G12*'Forecasting Assumptions'!G40 -> 6758311.1 | H41: =H12*'Forecasting Assumptions'!H40 -> 6971166.2 | I41: =I12*'Forecasting Assumptions'!I40 -> 7189567.1 | J41: =J12*'Forecasting Assumptions'!J40 -> 7413615.7 | K41: =K12*'Forecasting Assumptions'!K40 -> 7643414.6 | L41: =L12*'Forecasting Assumptions'!L40 -> 7879066.7 | M41: =M12*'Forecasting Assumptions'!M40 -> 8120675 | N41: =N12*'Forecasting Assumptions'!N40 -> 8368342.9 | ... R41: =R12*'Forecasting Assumptions'!R40 -> 9423202
A42: Total Assets | B42: =SUM(B37:B41) -> 16332800 | C42: =SUM(C37:C41) -> 13501200 | D42: =SUM(D37:D41) -> 19574600 | E42: =SUM(E37:E41) -> 20696000 | F42: =SUM(F37:F41) -> 21721800 | G42: =G37+G38+G39+G40+G41 -> 22409544 | H42: =H37+H38+H39+H40+H41 -> 23115340 | I42: =I37+I38+I39+I40+I41 -> 23839524 | J42: =J37+J38+J39+J40+J41 -> 24582436 | K42: =K37+K38+K39+K40+K41 -> 25344414 | L42: =L37+L38+L39+L40+L41 -> 26125801 | M42: =M37+M38+M39+M40+M41 -> 26926938 | N42: =N37+N38+N39+N40+N41 -> 27748168 | ... R42: =R37+R38+R39+R40+R41 -> 31245922
A44: Current Debt | B44: =B105 -> 915900 | C44: =C105 -> 0 | D44: =D105 -> 250000 | E44: =E105 -> 0 | F44: =F105 -> 0 | G44: =G42*'Forecasting Assumptions'!G45 -> 0 | H44: =H42*'Forecasting Assumptions'!H45 -> 0 | I44: =I42*'Forecasting Assumptions'!I45 -> 0 | J44: =J42*'Forecasting Assumptions'!J45 -> 0 | K44: =K42*'Forecasting Assumptions'!K45 -> 0 | L44: =L42*'Forecasting Assumptions'!L45 -> 0 | M44: =M42*'Forecasting Assumptions'!M45 -> 0 | N44: =N42*'Forecasting Assumptions'!N45 -> 0 | ... R44: =R42*'Forecasting Assumptions'!R45 -> 0
A45: Accounts Payable | B45: =B106 -> 1174800 | C45: =C106 -> 1416400 | D45: =D106 -> 1336500 | E45: =E106 -> 1480500 | F45: =F106 -> 1884200 | G45: =-G13*'Forecasting Assumptions'!G33 -> 1943856.5 | H45: =-H13*'Forecasting Assumptions'!H33 -> 2005078.9 | I45: =-I13*'Forecasting Assumptions'!I33 -> 2067896.4 | J45: =-J13*'Forecasting Assumptions'!J33 -> 2132338.3 | K45: =-K13*'Forecasting Assumptions'!K33 -> 2198434.1 | L45: =-L13*'Forecasting Assumptions'!L33 -> 2266213.4 | M45: =-M13*'Forecasting Assumptions'!M33 -> 2335705.9 | N45: =-N13*'Forecasting Assumptions'!N33 -> 2406941.3 | ... R45: =-R13*'Forecasting Assumptions'!R33 -> 2710344.7
...

Sheet Ratio Analysis
A1: Ratio Analysis
A4: Company Name | B4: ='Financial Statements'!B4 -> DOLLAR TREE 2021
B6: Actual | C6: Actual | D6: Actual | E6: Actual | F6: Actual | G6: Forecast | H6: Forecast | I6: Forecast | J6: Forecast | K6: Forecast | L6: Forecast | M6: Forecast | N6: Forecast | O6: Forecast | P6: Forecast | Q6: Forecast | R6: Forecast
A7: Fiscal Year End Date | B7: ='Financial Statements'!B8 -> 41669 | C7: ='Financial Statements'!C8 -> 42034 | D7: ='Financial Statements'!D8 -> 42399 | E7: ='Financial Statements'!E8 -> 42765 | F7: ='Financial Statements'!F8 -> 43130 | G7: ='Financial Statements'!G8 -> 43495 | H7: ='Financial Statements'!H8 -> 43860 | I7: ='Financial Statements'!I8 -> 44226 | ... R7: ='Financial Statements'!R8 -> 47513
A9: Annual Growth Rates
A10: Sales | C10: ='Financial Statements'!C12/'Financial Statements'!B12-1 -> 0.025973792 | D10: ='Financial Statements'!D12/'Financial Statements'!C12-1 -> 0.034504213 | E10: ='Financial Statements'!E12/'Financial Statements'!D12-1 -> 0.080408118 | F10: ='Financial Statements'!F12/'Financial Statements'!E12-1 -> 0.031827608 | G10: ='Financial Statements'!G12/'Financial Statements'!F12-1 -> 0.031661462 | H10: ='Financial Statements'!H12/'Financial Statements'!G12-1 -> 0.031495316 | I10: ='Financial Statements'!I12/'Financial Statements'!H12-1 -> 0.031329169 | J10: ='Financial Statements'!J12/'Financial Statements'!I12-1 -> 0.031163023 | ... R10: ='Financial Statements'!R12/'Financial Statements'!Q12-1 -> 0.03
A11: Assets | C11: =IF('Financial Statements'!B42<=0,#N/A,'Financial Statements'!C42/'Financial Statements'!B42-1) -> -0.17336893 | D11: =IF('Financial Statements'!C42<=0,#N/A,'Financial Statements'!D42/'Financial Statements'!C42-1) -> 0.4498415 | E11: =IF('Financial Statements'!D42<=0,#N/A,'Financial Statements'!E42/'Financial Statements'!D42-1) -> 0.057288527 | F11: =IF('Financial Statements'!E42<=0,#N/A,'Financial Statements'!F42/'Financial Statements'!E42-1) -> 0.049565133 | G11: =IF('Financial Statements'!F42<=0,#N/A,'Financial Statements'!G42/'Financial Statements'!F42-1) -> 0.031661462 | H11: =IF('Financial Statements'!G42<=0,#N/A,'Financial Statements'!H42/'Financial Statements'!G42-1) -> 0.031495316 | I11: =IF('Financial Statements'!H42<=0,#N/A,'Financial Statements'!I42/'Financial Statements'!H42-1) -> 0.031329169 | J11: =IF('Financial Statements'!I42<=0,#N/A,'Financial Statements'!J42/'Financial Statements'!I42-1) -> 0.031163023 | ... R11: =IF('Financial Statements'!Q42<=0,#N/A,'Financial Statements'!R42/'Financial Statements'!Q42-1) -> 0.03
A12: Common Equity | C12: =IF('Financial Statements'!B57<=0,#N/A,'Financial Statements'!C57/'Financial Statements'!B57-1) -> -0.21433246 | D12: =IF('Financial Statements'!C57<=0,#N/A,'Financial Statements'!D57/'Financial Statements'!C57-1) -> 0.10843715 | E12: =IF('Financial Statements'!D57<=0,#N/A,'Financial Statements'!E57/'Financial Statements'!D57-1) -> 0.16475347 | F12: =IF('Financial Statements'!E57<=0,#N/A,'Financial Statements'!F57/'Financial Statements'!E57-1) -> 0.059462205 | G12: =IF('Financial Statements'!F57<=0,#N/A,'Financial Statements'!G57/'Financial Statements'!F57-1) -> 0.031661462 | H12: =IF('Financial Statements'!G57<=0,#N/A,'Financial Statements'!H57/'Financial Statements'!G57-1) -> 0.031495316 | I12: =IF('Financial Statements'!H57<=0,#N/A,'Financial Statements'!I57/'Financial Statements'!H57-1) -> 0.031329169 | J12: =IF('Financial Statements'!I57<=0,#N/A,'Financial Statements'!J57/'Financial Statements'!I57-1) -> 0.031163023 | ... R12: =IF('Financial Statements'!Q57<=0,#N/A,'Financial Statements'!R57/'Financial Statements'!Q57-1) -> 0.03
A13: Earnings | C13: =IF('Financial Statements'!B29<=0,#N/A,'Financial Statements'!C29/'Financial Statements'!B29-1) -> -1.9279589 | D13: =IF('Financial Statements'!C29<=0,#N/A,'Financial Statements'!D29/'Financial Statements'!C29-1) -> #N/A | E13: =IF('Financial Statements'!D29<=0,#N/A,'Financial Statements'!E29/'Financial Statements'!D29-1) -> 0.62261185 | F13: =IF('Financial Statements'!E29<=0,#N/A,'Financial Statements'!F29/'Financial Statements'!E29-1) -> -0.010432968 | G13: =IF('Financial Statements'!F29<=0,#N/A,'Financial Statements'!G29/'Financial Statements'!F29-1) -> 0.030198756 | H13: =IF('Financial Statements'!G29<=0,#N/A,'Financial Statements'!H29/'Financial Statements'!G29-1) -> 0.031486223 | I13: =IF('Financial Statements'!H29<=0,#N/A,'Financial Statements'!I29/'Financial Statements'!H29-1) -> 0.031320076 | J13: =IF('Financial Statements'!I29<=0,#N/A,'Financial Statements'!J29/'Financial Statements'!I29-1) -> 0.031153928 | ... R13: =IF('Financial Statements'!Q29<=0,#N/A,'Financial Statements'!R29/'Financial Statements'!Q29-1) -> 0.03
A14: Free Cash Flow to Investors | D14: =IF('Cash Flow Analysis'!B116<=0,#N/A,'Cash Flow Analysis'!C116/'Cash Flow Analysis'!B116-1) -> -0.57761805 | E14: =IF('Cash Flow Analysis'!C116<=0,#N/A,'Cash Flow Analysis'!D116/'Cash Flow Analysis'!C116-1) -> 0.26943935 | F14: =IF('Cash Flow Analysis'!D116<=0,#N/A,'Cash Flow Analysis'!E116/'Cash Flow Analysis'!D116-1) -> -0.1251943 | G14: =IF('Cash Flow Analysis'!E116<=0,#N/A,'Cash Flow Analysis'!F116/'Cash Flow Analysis'!E116-1) -> 0.37446172 | H14: =IF('Cash Flow Analysis'!F116<=0,#N/A,'Cash Flow Analysis'!G116/'Cash Flow Analysis'!F116-1) -> 0.033079958 | I14: =IF('Cash Flow Analysis'!G116<=0,#N/A,'Cash Flow Analysis'!H116/'Cash Flow Analysis'!G116-1) -> 0.032911636 | J14: =IF('Cash Flow Analysis'!H116<=0,#N/A,'Cash Flow Analysis'!I116/'Cash Flow Analysis'!H116-1) -> 0.03274332 | K14: =IF('Cash Flow Analysis'!I116<=0,#N/A,'Cash Flow Analysis'!J116/'Cash Flow Analysis'!I116-1) -> 0.03257501 | ... R14: =IF('Cash Flow Analysis'!P116<=0,#N/A,'Cash Flow Analysis'!Q116/'Cash Flow Analysis'!P116-1) -> 0.03
A15: Sustainable Growth Rate | D15: =D19*(1-'Forecasting Assumptions'!D49) -> 0.13901847 | E15: =E19*(1-'Forecasting Assumptions'!E49) -> 0.19821124 | F15: =F19*(1-'Forecasting Assumptions'!F49) -> 0.17700849 | G15: =G19*(1-'Forecasting Assumptions'!G49) -> 0.17447457 | H15: =H19*(1-'Forecasting Assumptions'!H49) -> 0.1744592 | I15: =I19*(1-'Forecasting Assumptions'!I49) -> 0.17444383 | J15: =J19*(1-'Forecasting Assumptions'!J49) -> 0.17442845 | K15: =K19*(1-'Forecasting Assumptions'!K49) -> 0.17441308 | ... R15: =R19*(1-'Forecasting Assumptions'!R49) -> 0.17432076
A18: Profitability
A19: Return on Equity | C19: ='Financial Statements'!C73/(('Financial Statements'!B77+'Financial Statements'!C77)/2) -> -0.2480741 | D19: ='Financial Statements'!D73/(('Financial Statements'!C77+'Financial Statements'!D77)/2) -> 0.13901847 | E19: ='Financial Statements'!E73/(('Financial Statements'!D77+'Financial Statements'!E77)/2) -> 0.19821124 | F19: ='Financial Statements'!F73/(('Financial Statements'!E77+'Financial Statements'!F77)/2) -> 0.17700849 | G19: ='Financial Statements'!G73/(('Financial Statements'!F77+'Financial Statements'!G77)/2) -> 0.17447457 | H19: ='Financial Statements'!H73/(('Financial Statements'!G77+'Financial Statements'!H77)/2) -> 0.1744592 | I19: ='Financial Statements'!I73/(('Financial Statements'!H77+'Financial Statements'!I77)/2) -> 0.17444383 | J19: ='Financial Statements'!J73/(('Financial Statements'!I77+'Financial Statements'!J77)/2) -> 0.17442845 | ... R19: ='Financial Statements'!R73/(('Financial Statements'!Q77+'Financial Statements'!R77)/2) -> 0.17432076
A20: Return on Equity (b4 non-recurring) | C20: =('Financial Statements'!C29-'Financial Statements'!C26-'Financial Statements'!C24-((IF('Financial Statements'!C22=0,0,('Financial Statements'!C22+'Financial Statements'!C23)/'Financial Statements'!C22))*'Financial Statements'!C21))/(('Financial Statements'!B77+'Financial Statements'!C77)/2) -> -0.24816886 | D20: =('Financial Statements'!D29-'Financial Statements'!D26-'Financial Statements'!D24-((IF('Financial Statements'!D22=0,0,('Financial Statements'!D22+'Financial Statements'!D23)/'Financial Statements'!D22))*'Financial Statements'!D21))/(('Financial Statements'!C77+'Financial Statements'!D77)/2) -> 0.13919561 | E20: =('Financial Statements'!E29-'Financial Statements'!E26-'Financial Statements'!E24-((IF('Financial Statements'!E22=0,0,('Financial Statements'!E22+'Financial Statements'!E23)/'Financial Statements'!E22))*'Financial Statements'!E21))/(('Financial Statements'!D77+'Financial Statements'!E77)/2) -> 0.19830238 | F20: =('Financial Statements'!F29-'Financial Statements'!F26-'Financial Statements'!F24-((IF('Financial Statements'!F22=0,0,('Financial Statements'!F22+'Financial Statements'!F23)/'Financial Statements'!F22))*'Financial Statements'!F21))/(('Financial Statements'!E77+'Financial Statements'!F77)/2) -> 0.17704103 | G20: =('Financial Statements'!G29-'Financial Statements'!G26-'Financial Statements'!G24-((IF('Financial Statements'!G22=0,0,('Financial Statements'!G22+'Financial Statements'!G23)/'Financial Statements'!G22))*'Financial Statements'!G21))/(('Financial Statements'!F77+'Financial Statements'!G77)/2) -> 0.17450668 | H20: =('Financial Statements'!H29-'Financial Statements'!H26-'Financial Statements'!H24-((IF('Financial Statements'!H22=0,0,('Financial Statements'!H22+'Financial Statements'!H23)/'Financial Statements'!H22))*'Financial Statements'!H21))/(('Financial Statements'!G77+'Financial Statements'!H77)/2) -> 0.17449131 | I20: =('Financial Statements'!I29-'Financial Statements'!I26-'Financial Statements'!I24-((IF('Financial Statements'!I22=0,0,('Financial Statements'!I22+'Financial Statements'!I23)/'Financial Statements'!I22))*'Financial Statements'!I21))/(('Financial Statements'!H77+'Financial Statements'!I77)/2) -> 0.17447594 | J20: =('Financial Statements'!J29-'Financial Statements'!J26-'Financial Statements'!J24-((IF('Financial Statements'!J22=0,0,('Financial Statements'!J22+'Financial Statements'!J23)/'Financial Statements'!J22))*'Financial Statements'!J21))/(('Financial Statements'!I77+'Financial Statements'!J77)/2) -> 0.17446056 | ... R20: =('Financial Statements'!R29-'Financial Statements'!R26-'Financial Statements'!R24-((IF('Financial Statements'!R22=0,0,('Financial Statements'!R22+'Financial Statements'!R23)/'Financial Statements'!R22))*'Financial Statements'!R21))/(('Financial Statements'!Q77+'Financial Statements'!R77)/2) -> 0.17435285
A21: Return on Net Operating Assets | C21: ='Financial Statements'!C71/(('Financial Statements'!B75+'Financial Statements'!C75)/2) -> -0.10023909 | D21: ='Financial Statements'!D71/(('Financial Statements'!C75+'Financial Statements'!D75)/2) -> 0.095209873 | E21: ='Financial Statements'!E71/(('Financial Statements'!D75+'Financial Statements'!E75)/2) -> 0.14173497 | F21: ='Financial Statements'!F71/(('Financial Statements'!E75+'Financial Statements'!F75)/2) -> 0.13613403 | G21: ='Financial Statements'!G71/(('Financial Statements'!F75+'Financial Statements'!G75)/2) -> 0.13438183 | H21: ='Financial Statements'!H71/(('Financial Statements'!G75+'Financial Statements'!H75)/2) -> 0.13437118 | I21: ='Financial Statements'!I71/(('Financial Statements'!H75+'Financial Statements'!I75)/2) -> 0.13436053 | J21: ='Financial Statements'!J71/(('Financial Statements'!I75+'Financial Statements'!J75)/2) -> 0.13434987 | ... R21: ='Financial Statements'!R71/(('Financial Statements'!Q75+'Financial Statements'!R75)/2) -> 0.13427522
A23: Basic Dupont Model
A24: Net Profit Margin | B24: ='Financial Statements'!B29/'Financial Statements'!B12 -> 0.077062777 | C24: ='Financial Statements'!C29/'Financial Statements'!C12 -> -0.069700701 | D24: ='Financial Statements'!D29/'Financial Statements'!D12 -> 0.035026344 | E24: ='Financial Statements'!E29/'Financial Statements'!E12 -> 0.052604344 | F24: ='Financial Statements'!F29/'Financial Statements'!F12 -> 0.050449828 | G24: ='Financial Statements'!G29/'Financial Statements'!G12 -> 0.050378299 | H24: ='Financial Statements'!H29/'Financial Statements'!H12 -> 0.050377855 | I24: ='Financial Statements'!I29/'Financial Statements'!I12 -> 0.050377411 | ... R24: ='Financial Statements'!R29/'Financial Statements'!R12 -> 0.050373852
A25: x Total Asset Turnover | C25: ='Financial Statements'!C12/(('Financial Statements'!B42+'Financial Statements'!C42)/2) -> 1.5300194 | D25: ='Financial Statements'!D12/(('Financial Statements'!C42+'Financial Statements'!D42)/2) -> 1.4276782 | E25: ='Financial Statements'!E12/(('Financial Statements'!D42+'Financial Statements'!E42)/2) -> 1.2668945 | F25: ='Financial Statements'!F12/(('Financial Statements'!E42+'Financial Statements'!F42)/2) -> 1.241045 | G25: ='Financial Statements'!G12/(('Financial Statements'!F42+'Financial Statements'!G42)/2) -> 1.230625 | H25: ='Financial Statements'!H12/(('Financial Statements'!G42+'Financial Statements'!H42)/2) -> 1.2305274 | I25: ='Financial Statements'!I12/(('Financial Statements'!H42+'Financial Statements'!I42)/2) -> 1.2304299 | J25: ='Financial Statements'!J12/(('Financial Statements'!I42+'Financial Statements'!J42)/2) -> 1.2303323 | ... R25: ='Financial Statements'!R12/(('Financial Statements'!Q42+'Financial Statements'!R42)/2) -> 1.2296487
A26: x Total Leverage | C26: =('Financial Statements'!B58+'Financial Statements'!C58)/('Financial Statements'!B57+'Financial Statements'!C57) -> 2.3262015 | D26: =('Financial Statements'!C58+'Financial Statements'!D58)/('Financial Statements'!C57+'Financial Statements'!D57) -> 2.7800163 | E26: =('Financial Statements'!D58+'Financial Statements'!E58)/('Financial Statements'!D57+'Financial Statements'!E57) -> 2.974173 | F26: =('Financial Statements'!E58+'Financial Statements'!F58)/('Financial Statements'!E57+'Financial Statements'!F57) -> 2.8271371 | G26: =('Financial Statements'!F58+'Financial Statements'!G58)/('Financial Statements'!F57+'Financial Statements'!G57) -> 2.8142515 | H26: =('Financial Statements'!G58+'Financial Statements'!H58)/('Financial Statements'!G57+'Financial Statements'!H57) -> 2.8142515 | I26: =('Financial Statements'!H58+'Financial Statements'!I58)/('Financial Statements'!H57+'Financial Statements'!I57) -> 2.8142515 | J26: =('Financial Statements'!I58+'Financial Statements'!J58)/('Financial Statements'!I57+'Financial Statements'!J57) -> 2.8142515 | ... R26: =('Financial Statements'!Q58+'Financial Statements'!R58)/('Financial Statements'!Q57+'Financial Statements'!R57) -> 2.8142515
A27: = Return on Equity | C27: =C24*C25*C26 -> -0.2480741 | D27: =D24*D25*D26 -> 0.13901847 | E27: =E24*E25*E26 -> 0.19821124 | F27: =F24*F25*F26 -> 0.17700849 | G27: =G24*G25*G26 -> 0.17447457 | H27: =H24*H25*H26 -> 0.1744592 | I27: =I24*I25*I26 -> 0.17444383 | J27: =J24*J25*J26 -> 0.17442845 | ... R27: =R24*R25*R26 -> 0.17432076
A29: Advanced Dupont Model
A30: Net Operating Margin | B30: ='Financial Statements'!B71/'Financial Statements'!B12 -> 0.090711571 | C30: ='Financial Statements'!C71/'Financial Statements'!C12 -> -0.049999204 | D30: ='Financial Statements'!D71/'Financial Statements'!D12 -> 0.040194061 | E30: ='Financial Statements'!E71/'Financial Statements'!E12 -> 0.057058086 | F30: ='Financial Statements'!F71/'Financial Statements'!F12 -> 0.055979465 | G30: ='Financial Statements'!G71/'Financial Statements'!G12 -> 0.055979465 | H30: ='Financial Statements'!H71/'Financial Statements'!H12 -> 0.055979465 | I30: ='Financial Statements'!I71/'Financial Statements'!I12 -> 0.055979465 | ... R30: ='Financial Statements'!R71/'Financial Statements'!R12 -> 0.055979465
A31: x Net Operating Asset Turnover | C31: ='Financial Statements'!C12/(('Financial Statements'!B75+'Financial Statements'!C75)/2) -> 2.0048137 | D31: ='Financial Statements'!D12/(('Financial Statements'!C75+'Financial Statements'!D75)/2) -> 2.3687548 | E31: ='Financial Statements'!E12/(('Financial Statements'!D75+'Financial Statements'!E75)/2) -> 2.484047 | F31: ='Financial Statements'!F12/(('Financial Statements'!E75+'Financial Statements'!F75)/2) -> 2.4318566 | G31: ='Financial Statements'!G12/(('Financial Statements'!F75+'Financial Statements'!G75)/2) -> 2.4005559 | H31: ='Financial Statements'!H12/(('Financial Statements'!G75+'Financial Statements'!H75)/2) -> 2.4003656 | I31: ='Financial Statements'!I12/(('Financial Statements'!H75+'Financial Statements'!I75)/2) -> 2.4001753 | J31: ='Financial Statements'!J12/(('Financial Statements'!I75+'Financial Statements'!J75)/2) -> 2.3999849 | ... R31: ='Financial Statements'!R12/(('Financial Statements'!Q75+'Financial Statements'!R75)/2) -> 2.3986515
A32: = Return on Net Operating Assets | C32: =C30*C31 -> -0.10023909 | D32: =D30*D31 -> 0.095209873 | E32: =E30*E31 -> 0.14173497 | F32: =F30*F31 -> 0.13613403 | G32: =G30*G31 -> 0.13438183 | H32: =H30*H31 -> 0.13437118 | I32: =I30*I31 -> 0.13436053 | J32: =J30*J31 -> 0.13434987 | ... R32: =R30*R31 -> 0.13427522
A33: Net Borrowing Cost (NBC) | C33: =-'Financial Statements'!C72/(('Financial Statements'!B76+'Financial Statements'!C76)/2) -> 0.090443448 | D33: =-'Financial Statements'!D72/(('Financial Statements'!C76+'Financial Statements'!D76)/2) -> 0.030361163 | E33: =-'Financial Statements'!E72/(('Financial Statements'!D76+'Financial Statements'!E76)/2) -> 0.032467945 | F33: =-'Financial Statements'!F72/(('Financial Statements'!E76+'Financial Statements'!F76)/2) -> 0.043818248 | G33: =-'Financial Statements'!G72/(('Financial Statements'!F76+'Financial Statements'!G76)/2) -> 0.043818248 | H33: =-'Financial Statements'!H72/(('Financial Statements'!G76+'Financial Statements'!H76)/2) -> 0.043818248 | I33: =-'Financial Statements'!I72/(('Financial Statements'!H76+'Financial Statements'!I76)/2) -> 0.043818248 | J33: =-'Financial Statements'!J72/(('Financial Statements'!I76+'Financial Statements'!J76)/2) -> 0.043818248 | ... R33: =-'Financial Statements'!R72/(('Financial Statements'!Q76+'Financial Statements'!R76)/2) -> 0.043818248
A34: Spread (RNOA - NBC) | C34: =C32-C33 -> -0.19068254 | D34: =D32-D33 -> 0.064848709 | E34: =E32-E33 -> 0.10926702 | F34: =F32-F33 -> 0.092315784 | G34: =G32-G33 -> 0.090563587 | H34: =H32-H33 -> 0.090552934 | I34: =I32-I33 -> 0.090542279 | J34: =J32-J33 -> 0.090531622 | ... R34: =R32-R33 -> 0.090456977
A35: Financial Leverage (LEV) | C35: =('Financial Statements'!B76+'Financial Statements'!C76)/('Financial Statements'!B77+'Financial Statements'!C77) -> 0.77529395 | D35: =('Financial Statements'!C76+'Financial Statements'!D76)/('Financial Statements'!C77+'Financial Statements'!D77) -> 0.67555074 | E35: =('Financial Statements'!D76+'Financial Statements'!E76)/('Financial Statements'!D77+'Financial Statements'!E77) -> 0.51686472 | F35: =('Financial Statements'!E76+'Financial Statements'!F76)/('Financial Statements'!E77+'Financial Statements'!F77) -> 0.44276783 | G35: =('Financial Statements'!F76+'Financial Statements'!G76)/('Financial Statements'!F77+'Financial Statements'!G77) -> 0.4427026 | H35: =('Financial Statements'!G76+'Financial Statements'!H76)/('Financial Statements'!G77+'Financial Statements'!H77) -> 0.4427026 | I35: =('Financial Statements'!H76+'Financial Statements'!I76)/('Financial Statements'!H77+'Financial Statements'!I77) -> 0.4427026 | J35: =('Financial Statements'!I76+'Financial Statements'!J76)/('Financial Statements'!I77+'Financial Statements'!J77) -> 0.4427026 | ... R35: =('Financial Statements'!Q76+'Financial Statements'!R76)/('Financial Statements'!Q77+'Financial Statements'!R77) -> 0.4427026
A36: ROE = RNOA + LEV*Spread | C36: =C32+(C35*C34) -> -0.2480741 | D36: =D32+(D35*D34) -> 0.13901847 | E36: =E32+(E35*E34) -> 0.19821124 | F36: =F32+(F35*F34) -> 0.17700849 | G36: =G32+(G35*G34) -> 0.17447457 | H36: =H32+(H35*H34) -> 0.1744592 | I36: =I32+(I35*I34) -> 0.17444383 | J36: =J32+(J35*J34) -> 0.17442845 | ... R36: =R32+(R35*R34) -> 0.17432076
A39: Margin Analysis
A40: Gross Margin | B40: ='Financial Statements'!B14/'Financial Statements'!B12 -> 0.31565485 | C40: ='Financial Statements'!C14/'Financial Statements'!C12 -> 0.30440383 | D40: ='Financial Statements'!D14/'Financial Statements'!D12 -> 0.29819828 | E40: ='Financial Statements'!E14/'Financial Statements'!E12 -> 0.3052769 | F40: ='Financial Statements'!F14/'Financial Statements'!F12 -> 0.29352385 | G40: ='Financial Statements'!G14/'Financial Statements'!G12 -> 0.29352385 | H40: ='Financial Statements'!H14/'Financial Statements'!H12 -> 0.29352385 | I40: ='Financial Statements'!I14/'Financial Statements'!I12 -> 0.29352385 | ... R40: ='Financial Statements'!R14/'Financial Statements'!R12 -> 0.29352385
A41: EBITDA Margin | B41: ='Financial Statements'!B17/'Financial Statements'!B12 -> 0.092976108 | C41: ='Financial Statements'!C17/'Financial Statements'!C12 -> -0.041164074 | D41: ='Financial Statements'!D17/'Financial Statements'!D12 -> 0.053458587 | E41: ='Financial Statements'!E17/'Financial Statements'!E12 -> 0.074008303 | F41: ='Financial Statements'!F17/'Financial Statements'!F12 -> 0.068819051 | G41: ='Financial Statements'!G17/'Financial Statements'!G12 -> 0.068819051 | H41: ='Financial Statements'!H17/'Financial Statements'!H12 -> 0.068819051 | I41: ='Financial Statements'!I17/'Financial Statements'!I12 -> 0.068819051 | ... R41: ='Financial Statements'!R17/'Financial Statements'!R12 -> 0.068819051
A42: EBIT Margin | B42: ='Financial Statements'!B19/'Financial Statements'!B12 -> 0.089865366 | C42: ='Financial Statements'!C19/'Financial Statements'!C12 -> -0.041164074 | D42: ='Financial Statements'!D19/'Financial Statements'!D12 -> 0.053458587 | E42: ='Financial Statements'!E19/'Financial Statements'!E12 -> 0.074008303 | F42: ='Financial Statements'!F19/'Financial Statements'!F12 -> 0.068819051 | G42: ='Financial Statements'!G19/'Financial Statements'!G12 -> 0.068819051 | H42: ='Financial Statements'!H19/'Financial Statements'!H12 -> 0.068819051 | I42: ='Financial Statements'!I19/'Financial Statements'!I12 -> 0.068819051 | ... R42: ='Financial Statements'!R19/'Financial Statements'!R12 -> 0.068819051
A43: Net Operating Margin (b4 non-rec.) | B43: =('Financial Statements'!B71-'Financial Statements'!B21*(1-'Forecasting Assumptions'!B21)-'Financial Statements'!B26-'Financial Statements'!B24)/'Financial Statements'!B12 -> 0.090408566 | C43: =('Financial Statements'!C71-'Financial Statements'!C21*(1-'Forecasting Assumptions'!C21)-'Financial Statements'!C26-'Financial Statements'!C24)/'Financial Statements'!C12 -> -0.050025828 | D43: =('Financial Statements'!D71-'Financial Statements'!D21*(1-'Forecasting Assumptions'!D21)-'Financial Statements'!D26-'Financial Statements'!D24)/'Financial Statements'!D12 -> 0.040238692 | E43: =('Financial Statements'!E71-'Financial Statements'!E21*(1-'Forecasting Assumptions'!E21)-'Financial Statements'!E26-'Financial Statements'!E24)/'Financial Statements'!E12 -> 0.057082275 | F43: =('Financial Statements'!F71-'Financial Statements'!F21*(1-'Forecasting Assumptions'!F21)-'Financial Statements'!F26-'Financial Statements'!F24)/'Financial Statements'!F12 -> 0.055988738 | G43: =('Financial Statements'!G71-'Financial Statements'!G21*(1-'Forecasting Assumptions'!G21)-'Financial Statements'!G26-'Financial Statements'!G24)/'Financial Statements'!G12 -> 0.055988738 | H43: =('Financial Statements'!H71-'Financial Statements'!H21*(1-'Forecasting Assumptions'!H21)-'Financial Statements'!H26-'Financial Statements'!H24)/'Financial Statements'!H12 -> 0.055988738 | I43: =('Financial Statements'!I71-'Financial Statements'!I21*(1-'Forecasting Assumptions'!I21)-'Financial Statements'!I26-'Financial Statements'!I24)/'Financial Statements'!I12 -> 0.055988738 | ... R43: =('Financial Statements'!R71-'Financial Statements'!R21*(1-'Forecasting Assumptions'!R21)-'Financial Statements'!R26-'Financial Statements'!R24)/'Financial Statements'!R12 -> 0.055988738
A44: Net Operating Margin | B44: ='Financial Statements'!B71/'Financial Statements'!B12 -> 0.090711571 | C44: ='Financial Statements'!C71/'Financial Statements'!C12 -> -0.049999204 | D44: ='Financial Statements'!D71/'Financial Statements'!D12 -> 0.040194061 | E44: ='Financial Statements'!E71/'Financial Statements'!E12 -> 0.057058086 | F44: ='Financial Statements'!F71/'Financial Statements'!F12 -> 0.055979465 | G44: ='Financial Statements'!G71/'Financial Statements'!G12 -> 0.055979465 | H44: ='Financial Statements'!H71/'Financial Statements'!H12 -> 0.055979465 | I44: ='Financial Statements'!I71/'Financial Statements'!I12 -> 0.055979465 | ... R44: ='Financial Statements'!R71/'Financial Statements'!R12 -> 0.055979465
A46: Turnover Analysis
A47: Net Operating Asset Turnover | C47: ='Financial Statements'!C12/(('Financial Statements'!C75+'Financial Statements'!B75)/2) -> 2.0048137 | D47: ='Financial Statements'!D12/(('Financial Statements'!D75+'Financial Statements'!C75)/2) -> 2.3687548 | E47: ='Financial Statements'!E12/(('Financial Statements'!E75+'Financial Statements'!D75)/2) -> 2.484047 | F47: ='Financial Statements'!F12/(('Financial Statements'!F75+'Financial Statements'!E75)/2) -> 2.4318566 | G47: ='Financial Statements'!G12/(('Financial Statements'!G75+'Financial Statements'!F75)/2) -> 2.4005559 | H47: ='Financial Statements'!H12/(('Financial Statements'!H75+'Financial Statements'!G75)/2) -> 2.4003656 | I47: ='Financial Statements'!I12/(('Financial Statements'!I75+'Financial Statements'!H75)/2) -> 2.4001753 | J47: ='Financial Statements'!J12/(('Financial Statements'!J75+'Financial Statements'!I75)/2) -> 2.3999849 | ... R47: ='Financial Statements'!R12/(('Financial Statements'!R75+'Financial Statements'!Q75)/2) -> 2.3986515
A48: Net Working Capital Turnover | C48: ='Financial Statements'!C12/(('Financial Statements'!B37-'Financial Statements'!B48+'Financial Statements'!B44+'Financial Statements'!C37-'Financial Statements'!C48+'Financial Statements'!C44)/2) -> 9.4492724 | D48: ='Financial Statements'!D12/(('Financial Statements'!C37-'Financial Statements'!C48+'Financial Statements'!C44+'Financial Statements'!D37-'Financial Statements'!D48+'Financial Statements'!D44)/2) -> 14.894055 | E48: ='Financial Statements'!E12/(('Financial Statements'!D37-'Financial Statements'!D48+'Financial Statements'!D44+'Financial Statements'!E37-'Financial Statements'!E48+'Financial Statements'!E44)/2) -> 22.245836 | F48: ='Financial Statements'!F12/(('Financial Statements'!E37-'Financial Statements'!E48+'Financial Statements'!E44+'Financial Statements'!F37-'Financial Statements'!F48+'Financial Statements'!F44)/2) -> 19.121136 | G48: ='Financial Statements'!G12/(('Financial Statements'!F37-'Financial Statements'!F48+'Financial Statements'!F44+'Financial Statements'!G37-'Financial Statements'!G48+'Financial Statements'!G44)/2) -> 18.659354 | H48: ='Financial Statements'!H12/(('Financial Statements'!G37-'Financial Statements'!G48+'Financial Statements'!G44+'Financial Statements'!H37-'Financial Statements'!H48+'Financial Statements'!H44)/2) -> 18.657875 | I48: ='Financial Statements'!I12/(('Financial Statements'!H37-'Financial Statements'!H48+'Financial Statements'!H44+'Financial Statements'!I37-'Financial Statements'!I48+'Financial Statements'!I44)/2) -> 18.656395 | J48: ='Financial Statements'!J12/(('Financial Statements'!I37-'Financial Statements'!I48+'Financial Statements'!I44+'Financial Statements'!J37-'Financial Statements'!J48+'Financial Statements'!J44)/2) -> 18.654915 | ... R48: ='Financial Statements'!R12/(('Financial Statements'!Q37-'Financial Statements'!Q48+'Financial Statements'!Q44+'Financial Statements'!R37-'Financial Statements'!R48+'Financial Statements'!R44)/2) -> 18.644551
A49: Avge Days to Collect Receivables | C49: =365*((('Financial Statements'!B34+'Financial Statements'!C34)/2)/'Financial Statements'!C12) -> 0.80681803 | D49: =365*((('Financial Statements'!C34+'Financial Statements'!D34)/2)/'Financial Statements'!D12) -> 0.77990792 | E49: =365*((('Financial Statements'!D34+'Financial Statements'!E34)/2)/'Financial Statements'!E12) -> 0 | F49: =365*((('Financial Statements'!E34+'Financial Statements'!F34)/2)/'Financial Statements'!F12) -> 0 | G49: =365*((('Financial Statements'!F34+'Financial Statements'!G34)/2)/'Financial Statements'!G12) -> 0 | H49: =365*((('Financial Statements'!G34+'Financial Statements'!H34)/2)/'Financial Statements'!H12) -> 0 | I49: =365*((('Financial Statements'!H34+'Financial Statements'!I34)/2)/'Financial Statements'!I12) -> 0 | J49: =365*((('Financial Statements'!I34+'Financial Statements'!J34)/2)/'Financial Statements'!J12) -> 0 | ... R49: =365*((('Financial Statements'!Q34+'Financial Statements'!R34)/2)/'Financial Statements'!R12) -> 0
A50: Avge Inventory Holding Period | C50: =-365*((('Financial Statements'!B35+'Financial Statements'!C35)/2)/'Financial Statements'!C13) -> 77.080667 | D50: =-365*((('Financial Statements'!C35+'Financial Statements'!D35)/2)/'Financial Statements'!D13) -> 77.735499 | E50: =-365*((('Financial Statements'!D35+'Financial Statements'!E35)/2)/'Financial Statements'!E13) -> 71.560753 | F50: =-365*((('Financial Statements'!E35+'Financial Statements'!F35)/2)/'Financial Statements'!F13) -> 76.49566 | G50: =-365*((('Financial Statements'!F35+'Financial Statements'!G35)/2)/'Financial Statements'!G13) -> 84.408628 | H50: =-365*((('Financial Statements'!G35+'Financial Statements'!H35)/2)/'Financial Statements'!H13) -> 84.41532 | I50: =-365*((('Financial Statements'!H35+'Financial Statements'!I35)/2)/'Financial Statements'!I13) -> 84.422014 | J50: =-365*((('Financial Statements'!I35+'Financial Statements'!J35)/2)/'Financial Statements'!J13) -> 84.42871 | ... R50: =-365*((('Financial Statements'!Q35+'Financial Statements'!R35)/2)/'Financial Statements'!R13) -> 84.475645
A51: Avge Days to Pay Payables | C51: =365*((('Financial Statements'!B45+'Financial Statements'!C45)/2)/(-'Financial Statements'!C13+'Financial Statements'!C35-'Financial Statements'!B35)) -> 29.114607 | D51: =365*((('Financial Statements'!C45+'Financial Statements'!D45)/2)/(-'Financial Statements'!D13+'Financial Statements'!D35-'Financial Statements'!C35)) -> 30.345567 | E51: =365*((('Financial Statements'!D45+'Financial Statements'!E45)/2)/(-'Financial Statements'!E13+'Financial Statements'!E35-'Financial Statements'!D35)) -> 29.165792 | F51: =365*((('Financial Statements'!E45+'Financial Statements'!F45)/2)/(-'Financial Statements'!F13+'Financial Statements'!F35-'Financial Statements'!E35)) -> 31.432756 | G51: =365*((('Financial Statements'!F45+'Financial Statements'!G45)/2)/(-'Financial Statements'!G13+'Financial Statements'!G35-'Financial Statements'!F35)) -> 36.156112 | H51: =365*((('Financial Statements'!G45+'Financial Statements'!H45)/2)/(-'Financial Statements'!H13+'Financial Statements'!H35-'Financial Statements'!G35)) -> 36.160295 | I51: =365*((('Financial Statements'!H45+'Financial Statements'!I45)/2)/(-'Financial Statements'!I13+'Financial Statements'!I35-'Financial Statements'!H35)) -> 36.16448 | J51: =365*((('Financial Statements'!I45+'Financial Statements'!J45)/2)/(-'Financial Statements'!J13+'Financial Statements'!J35-'Financial Statements'!I35)) -> 36.168666 | ... R51: =365*((('Financial Statements'!Q45+'Financial Statements'!R45)/2)/(-'Financial Statements'!R13+'Financial Statements'!R35-'Financial Statements'!Q35)) -> 36.198017
...

Sheet Cash Flow Analysis
A1: Cash Flow Analysis | B1: ($000)
A4: Company Name | B4: ='Financial Statements'!B4 -> DOLLAR TREE 2021
B6: Actual | C6: Actual | D6: Actual | E6: Actual | F6: Forecast | G6: Forecast | H6: Forecast | I6: Forecast | J6: Forecast | K6: Forecast | L6: Forecast | M6: Forecast | N6: Forecast | O6: Forecast | P6: Forecast | Q6: Forecast
A7: Fiscal Year End Date | B7: ='Financial Statements'!C8 -> 42034 | C7: ='Financial Statements'!D8 -> 42399 | D7: ='Financial Statements'!E8 -> 42765 | E7: ='Financial Statements'!F8 -> 43130 | F7: ='Financial Statements'!G8 -> 43495 | G7: ='Financial Statements'!H8 -> 43860 | H7: ='Financial Statements'!I8 -> 44226 | I7: ='Financial Statements'!J8 -> 44591 | ... Q7: ='Financial Statements'!R8 -> 47513
A8: Pro Forma Statement of Cash Flows
A10: Operating:
A11: Net Income | B11: ='Financial Statements'!C29 -> -1590800 | C11: ='Financial Statements'!D29 -> 827000 | D11: ='Financial Statements'!E29 -> 1341900 | E11: ='Financial Statements'!F29 -> 1327900 | F11: ='Financial Statements'!G29 -> 1368000.9 | G11: ='Financial Statements'!H29 -> 1411074.1 | H11: ='Financial Statements'!I29 -> 1455269.1 | I11: ='Financial Statements'!J29 -> 1500606.4 | ... Q11: ='Financial Statements'!R29 -> 1907253.3
A12: +Depreciation & Amortization | B12: =-'Financial Statements'!C18 -> 0 | C12: =-'Financial Statements'!D18 -> 0 | D12: =-'Financial Statements'!E18 -> 0 | E12: =-'Financial Statements'!F18 -> 0 | F12: =-'Financial Statements'!G18 -> 0 | G12: =-'Financial Statements'!H18 -> 0 | H12: =-'Financial Statements'!I18 -> 0 | I12: =-'Financial Statements'!J18 -> 0 | ... Q12: =-'Financial Statements'!R18 -> 0
A13: +Increase in Deferred Taxes | B13: ='Financial Statements'!C51-'Financial Statements'!B51 -> -12000 | C13: ='Financial Statements'!D51-'Financial Statements'!C51 -> 11500 | D13: ='Financial Statements'!E51-'Financial Statements'!D51 -> 28800 | E13: ='Financial Statements'!F51-'Financial Statements'!E51 -> -26300 | F13: ='Financial Statements'!G51-'Financial Statements'!F51 -> 31256.195 | G13: ='Financial Statements'!H51-'Financial Statements'!G51 -> 32076.599 | H13: ='Financial Statements'!I51-'Financial Statements'!H51 -> 32912.32 | I13: ='Financial Statements'!J51-'Financial Statements'!I51 -> 33763.425 | ... Q13: ='Financial Statements'!R51-'Financial Statements'!Q51 -> 41360.589
A14: +Increase in Other Liabilities | B14: ='Financial Statements'!C50-'Financial Statements'!B50 -> -20000 | C14: ='Financial Statements'!D50-'Financial Statements'!C50 -> 4742300 | D14: ='Financial Statements'!E50-'Financial Statements'!D50 -> 174300 | E14: ='Financial Statements'!F50-'Financial Statements'!E50 -> -18200 | F14: ='Financial Statements'!G50-'Financial Statements'!F50 -> 171684.28 | G14: ='Financial Statements'!H50-'Financial Statements'!G50 -> 176190.6 | H14: ='Financial Statements'!I50-'Financial Statements'!H50 -> 180781.05 | I14: ='Financial Statements'!J50-'Financial Statements'!I50 -> 185456.01 | ... Q14: ='Financial Statements'!R50-'Financial Statements'!Q50 -> 227185.77
A15: +Noncontrolling Interest in Earnings | B15: =-'Financial Statements'!C27 -> 0 | C15: =-'Financial Statements'!D27 -> 0 | D15: =-'Financial Statements'!E27 -> 0 | E15: =-'Financial Statements'!F27 -> 0 | F15: =-'Financial Statements'!G27 -> 0 | G15: =-'Financial Statements'!H27 -> 0 | H15: =-'Financial Statements'!I27 -> 0 | I15: =-'Financial Statements'!J27 -> 0 | ... Q15: =-'Financial Statements'!R27 -> 0
A16: +Preferred Dividends | B16: =-'Financial Statements'!C28 -> 0 | C16: =-'Financial Statements'!D28 -> 0 | D16: =-'Financial Statements'!E28 -> 0 | E16: =-'Financial Statements'!F28 -> 0 | F16: =-'Financial Statements'!G28 -> 0 | G16: =-'Financial Statements'!H28 -> 0 | H16: =-'Financial Statements'!I28 -> 0 | I16: =-'Financial Statements'!J28 -> 0 | ... Q16: =-'Financial Statements'!R28 -> 0
A17: =Funds From Operations | B17: =B11+B12+B13+B14+B15+B16 -> -1622800 | C17: =C11+C12+C13+C14+C15+C16 -> 5580800 | D17: =D11+D12+D13+D14+D15+D16 -> 1545000 | E17: =E11+E12+E13+E14+E15+E16 -> 1283400 | F17: =F11+F12+F13+F14+F15+F16 -> 1570941.4 | G17: =G11+G12+G13+G14+G15+G16 -> 1619341.3 | H17: =H11+H12+H13+H14+H15+H16 -> 1668962.4 | I17: =I11+I12+I13+I14+I15+I16 -> 1719825.8 | ... Q17: =Q11+Q12+Q13+Q14+Q15+Q16 -> 2175799.7
A18: -Increase in Receivables | B18: =-('Financial Statements'!C34-'Financial Statements'!B34) -> -100900 | C18: =-('Financial Statements'!D34-'Financial Statements'!C34) -> 100900 | D18: =-('Financial Statements'!E34-'Financial Statements'!D34) -> 0 | E18: =-('Financial Statements'!F34-'Financial Statements'!E34) -> 0 | F18: =-('Financial Statements'!G34-'Financial Statements'!F34) -> 0 | G18: =-('Financial Statements'!H34-'Financial Statements'!G34) -> 0 | H18: =-('Financial Statements'!I34-'Financial Statements'!H34) -> 0 | I18: =-('Financial Statements'!J34-'Financial Statements'!I34) -> 0 | ... Q18: =-('Financial Statements'!R34-'Financial Statements'!Q34) -> 0
A19: -Increase in Inventory | B19: =-('Financial Statements'!C35-'Financial Statements'!B35) -> -366700 | C19: =-('Financial Statements'!D35-'Financial Statements'!C35) -> 14000 | D19: =-('Financial Statements'!E35-'Financial Statements'!D35) -> 95000 | E19: =-('Financial Statements'!F35-'Financial Statements'!E35) -> -940300 | F19: =-('Financial Statements'!G35-'Financial Statements'!F35) -> -138275.1 | G19: =-('Financial Statements'!H35-'Financial Statements'!G35) -> -141904.51 | H19: =-('Financial Statements'!I35-'Financial Statements'!H35) -> -145601.68 | I19: =-('Financial Statements'!J35-'Financial Statements'!I35) -> -149366.9 | ... Q19: =-('Financial Statements'!R35-'Financial Statements'!Q35) -> -182976.19
A20: -Increase in Other Current Assets | B20: =-('Financial Statements'!C36-'Financial Statements'!B36) -> 99500 | C20: =-('Financial Statements'!D36-'Financial Statements'!C36) -> 48300 | D20: =-('Financial Statements'!E36-'Financial Statements'!D36) -> 1200 | E20: =-('Financial Statements'!F36-'Financial Statements'!E36) -> -43400 | F20: =-('Financial Statements'!G36-'Financial Statements'!F36) -> -6446.2736 | G20: =-('Financial Statements'!H36-'Financial Statements'!G36) -> -6615.4737 | H20: =-('Financial Statements'!I36-'Financial Statements'!H36) -> -6787.8326 | I20: =-('Financial Statements'!J36-'Financial Statements'!I36) -> -6963.3645 | ... Q20: =-('Financial Statements'!R36-'Financial Statements'!Q36) -> -8530.2024
A21: +Increase in Accounts Payable | B21: =('Financial Statements'!C45-'Financial Statements'!B45) -> 241600 | C21: =('Financial Statements'!D45-'Financial Statements'!C45) -> -79900 | D21: =('Financial Statements'!E45-'Financial Statements'!D45) -> 144000 | E21: =('Financial Statements'!F45-'Financial Statements'!E45) -> 403700 | F21: =('Financial Statements'!G45-'Financial Statements'!F45) -> 59656.526 | G21: =('Financial Statements'!H45-'Financial Statements'!G45) -> 61222.375 | H21: =('Financial Statements'!I45-'Financial Statements'!H45) -> 62817.457 | I21: =('Financial Statements'!J45-'Financial Statements'!I45) -> 64441.902 | ... Q21: =('Financial Statements'!R45-'Financial Statements'!Q45) -> 78942.08
A22: +Increase in Taxes Payable | B22: =('Financial Statements'!C46-'Financial Statements'!B46) -> 28500 | C22: =('Financial Statements'!D46-'Financial Statements'!C46) -> 2700 | D22: =('Financial Statements'!E46-'Financial Statements'!D46) -> 23600 | E22: =('Financial Statements'!F46-'Financial Statements'!E46) -> -3700 | F22: =('Financial Statements'!G46-'Financial Statements'!F46) -> 2615.2367 | G22: =('Financial Statements'!H46-'Financial Statements'!G46) -> 2683.8808 | H22: =('Financial Statements'!I46-'Financial Statements'!H46) -> 2753.8063 | I22: =('Financial Statements'!J46-'Financial Statements'!I46) -> 2825.0192 | ... Q22: =('Financial Statements'!R46-'Financial Statements'!Q46) -> 3460.6813
A23: +Increase in Other Curr. Liabilities | B23: =('Financial Statements'!C47-'Financial Statements'!B47) -> -117600 | C23: =('Financial Statements'!D47-'Financial Statements'!C47) -> 1278000 | D23: =('Financial Statements'!E47-'Financial Statements'!D47) -> 266200 | E23: =('Financial Statements'!F47-'Financial Statements'!E47) -> 46300 | F23: =('Financial Statements'!G47-'Financial Statements'!F47) -> 69965.498 | G23: =('Financial Statements'!H47-'Financial Statements'!G47) -> 71801.934 | H23: =('Financial Statements'!I47-'Financial Statements'!H47) -> 73672.655 | I23: =('Financial Statements'!J47-'Financial Statements'!I47) -> 75577.813 | ... Q23: =('Financial Statements'!R47-'Financial Statements'!Q47) -> 92583.7
A24: =Cash From Operations | B24: =B17+B18+B19+B20+B21+B22+B23 -> -1838400 | C24: =C17+C18+C19+C20+C21+C22+C23 -> 6944800 | D24: =D17+D18+D19+D20+D21+D22+D23 -> 2075000 | E24: =E17+E18+E19+E20+E21+E22+E23 -> 746000 | F24: =F17+F18+F19+F20+F21+F22+F23 -> 1558457.3 | G24: =G17+G18+G19+G20+G21+G22+G23 -> 1606529.5 | H24: =H17+H18+H19+H20+H21+H22+H23 -> 1655816.8 | I24: =I17+I18+I19+I20+I21+I22+I23 -> 1706340.3 | ... Q24: =Q17+Q18+Q19+Q20+Q21+Q22+Q23 -> 2159279.7
A26: Investing:
A27: -Capital Expenditures | B27: =-('Financial Statements'!C38-'Financial Statements'!B38-'Financial Statements'!C18) -> -244600 | C27: =-('Financial Statements'!D38-'Financial Statements'!C38-'Financial Statements'!D18) -> -436500 | D27: =-('Financial Statements'!E38-'Financial Statements'!D38-'Financial Statements'!E18) -> -234500 | E27: =-('Financial Statements'!F38-'Financial Statements'!E38-'Financial Statements'!F18) -> -361000 | F27: =-('Financial Statements'!G38-'Financial Statements'!F38-'Financial Statements'!G18) -> -141757.86 | G27: =-('Financial Statements'!H38-'Financial Statements'!G38-'Financial Statements'!H18) -> -145478.69 | H27: =-('Financial Statements'!I38-'Financial Statements'!H38-'Financial Statements'!I18) -> -149268.97 | I27: =-('Financial Statements'!J38-'Financial Statements'!I38-'Financial Statements'!J18) -> -153129.04 | ... Q27: =-('Financial Statements'!R38-'Financial Statements'!Q38-'Financial Statements'!R18) -> -187584.85
