Workbook

Sheet Case Data
A9: Item | B9: Year 1 | C9: Year 2 | D9: Year 3 | E9: Year 4 | F9: Year 5
A10: Company Name | B10: Zoom Communications, Inc. | C10: Ticker | D10: ZM | E10: SIC
A11: Common Shares Outstanding
A12: Fiscal Year End | B12: 44560
A13: Sales | B13: 4665.433
A14: Cost of Goods Sold
A15: R&D | B15: 852.415
A16: SG&A
A17: Depreciation
A18: Interest Expense
A19: Non-Operating Income | B19: 325.147
A20: Income Tax | B20: 305.346
A21: Noncontrolling Interest
A22: Other Income | B22: 325.147
A23: Extraordinary Items
A24: Preferred Dividends
A25: Cash and Cash Equivalents | B25: 1349.38
A26: Receivables | B26: 495.228
A27: Inventories
A28: Other Current Assets | B28: 200.679
A29: Property, Plant and Equipment | B29: 330.475
A30: Investments | B30: 591.481
A31: Intangible Assets | B31: 307.295
A32: Other Assets
A33: Current Debt
A34: Accounts Payable | B34: 8.345
A35: Income Taxes Payable
A36: Other Current Liabilities | B36: 558.562
A37: Long-Term Debt
A38: Other Liabilities
A39: Deferred Taxes | B39: 749.759
A40: Noncontrolling Interest
A41: Preferred Stock
A42: Paid in Capital | B42: 0.305
A43: Retained Earnings | B43: 3799.518

Sheet Intro
A19: STEPS:
A20: 1) enter financial data on the Financial Statements sheet,
A21: 2) examine the Ratio Analysis and Cash Flow Analysis,
A22: 3) enter forecasts on the Forecasting Assumptions sheet to predict the future Financial Statements,
A23: 4) enter cost of capital assumptions on the Valuation Parameters Sheet to determine the company's value,
A24: 5) evaluate the details of the resulting valuation using either the Residual Income or Discounted Cash Flow Valuations.

Sheet Financial Statements
A1: Financial Statements | B1: ($000s) | C1: Data can be entered manually in financial statements or as a block cut-and-paste from the Case Data Sheet to the Raw Data Input section below.
C3: Jump to Raw Data Input
A4: Company Name, Ticker and SIC | B4: =B82 | D4: =D82 | E4: =F82 | F4: =IF(D4="","",HYPERLINK(CONCATENATE("http://www.sec.gov/cgi-bin/browse-edgar?type=10-K&action=getcompany&CIK=",D4),"Link to Form 10-Ks"))
A5: Common Shares Outstanding | B5: =B83 | C5: (in 000s at most recent fiscal year end) | F5: Link to Industry Comps
A6: ="Estimated Price/Share="&DOLLAR('Valuation Parameters'!B24)
B7: Actual | C7: Actual | D7: Actual | E7: Actual | F7: Actual | G7: Forecast | H7: Forecast | I7: Forecast | J7: Forecast | K7: Forecast | L7: Forecast | M7: Forecast | N7: Forecast | O7: Forecast | P7: Forecast | Q7: Forecast | R7: Forecast
A8: Fiscal Year End (YYYY-MM-DD) | B8: =B84 | C8: =C84 | D8: =D84 | E8: =E84 | F8: =F84 | G8: =DATE(YEAR(F8)+1,MONTH(F8),DAY(F8)) | H8: =DATE(YEAR(G8)+1,MONTH(G8),DAY(G8)) | I8: =DATE(YEAR(H8)+1,MONTH(H8),DAY(H8)) | J8: =DATE(YEAR(I8)+1,MONTH(I8),DAY(I8)) | K8: =DATE(YEAR(J8)+1,MONTH(J8),DAY(J8)) | L8: =DATE(YEAR(K8)+1,MONTH(K8),DAY(K8)) | M8: =DATE(YEAR(L8)+1,MONTH(L8),DAY(L8)) | N8: =DATE(YEAR(M8)+1,MONTH(M8),DAY(M8)) | ... R8: =DATE(YEAR(Q8)+1,MONTH(Q8),DAY(Q8))
A10: Income Statement
A12: Sales (Net) | B12: =B85 | C12: =C85 | D12: =D85 | E12: =E85 | F12: =F85 | G12: =F12*(1+'Forecasting Assumptions'!G14) | H12: =G12*(1+'Forecasting Assumptions'!H14) | I12: =H12*(1+'Forecasting Assumptions'!I14) | J12: =I12*(1+'Forecasting Assumptions'!J14) | K12: =J12*(1+'Forecasting Assumptions'!K14) | L12: =K12*(1+'Forecasting Assumptions'!L14) | M12: =L12*(1+'Forecasting Assumptions'!M14) | N12: =M12*(1+'Forecasting Assumptions'!N14) | ... R12: =Q12*(1+'Forecasting Assumptions'!R14)
A13: Cost of Goods Sold | B13: =B86 | C13: =C86 | D13: =D86 | E13: =E86 | F13: =F86 | G13: =-G12*'Forecasting Assumptions'!G15 | H13: =-H12*'Forecasting Assumptions'!H15 | I13: =-I12*'Forecasting Assumptions'!I15 | J13: =-J12*'Forecasting Assumptions'!J15 | K13: =-K12*'Forecasting Assumptions'!K15 | L13: =-L12*'Forecasting Assumptions'!L15 | M13: =-M12*'Forecasting Assumptions'!M15 | N13: =-N12*'Forecasting Assumptions'!N15 | ... R13: =-R12*'Forecasting Assumptions'!R15
A14: Gross Profit | B14: =B12+B13 | C14: =C12+C13 | D14: =D12+D13 | E14: =E12+E13 | F14: =F12+F13 | G14: =G12+G13 | H14: =H12+H13 | I14: =I12+I13 | ... R14: =R12+R13
A15: R&D Expense | B15: =B87 | C15: =C87 | D15: =D87 | E15: =E87 | F15: =F87 | G15: =-G12*'Forecasting Assumptions'!G16 | H15: =-H12*'Forecasting Assumptions'!H16 | I15: =-I12*'Forecasting Assumptions'!I16 | J15: =-J12*'Forecasting Assumptions'!J16 | K15: =-K12*'Forecasting Assumptions'!K16 | L15: =-L12*'Forecasting Assumptions'!L16 | M15: =-M12*'Forecasting Assumptions'!M16 | N15: =-N12*'Forecasting Assumptions'!N16 | ... R15: =-R12*'Forecasting Assumptions'!R16
A16: SG&A Expense | B16: =B88 | C16: =C88 | D16: =D88 | E16: =E88 | F16: =F88 | G16: =-G12*'Forecasting Assumptions'!G17 | H16: =-H12*'Forecasting Assumptions'!H17 | I16: =-I12*'Forecasting Assumptions'!I17 | J16: =-J12*'Forecasting Assumptions'!J17 | K16: =-K12*'Forecasting Assumptions'!K17 | L16: =-L12*'Forecasting Assumptions'!L17 | M16: =-M12*'Forecasting Assumptions'!M17 | N16: =-N12*'Forecasting Assumptions'!N17 | ... R16: =-R12*'Forecasting Assumptions'!R17
A17: EBITDA | B17: =B14+B15+B16 | C17: =C14+C15+C16 | D17: =D14+D15+D16 | E17: =E14+E15+E16 | F17: =F14+F15+F16 | G17: =G14+G15+G16 | H17: =H14+H15+H16 | I17: =I14+I15+I16 | ... R17: =R14+R15+R16
A18: Depreciation & Amortization | B18: =B89 | C18: =C89 | D18: =D89 | E18: =E89 | F18: =F89 | G18: =-((F38+G38+F40+G40)/2)*'Forecasting Assumptions'!G18 | H18: =-((G38+H38+G40+H40)/2)*'Forecasting Assumptions'!H18 | I18: =-((H38+I38+H40+I40)/2)*'Forecasting Assumptions'!I18 | J18: =-((I38+J38+I40+J40)/2)*'Forecasting Assumptions'!J18 | K18: =-((J38+K38+J40+K40)/2)*'Forecasting Assumptions'!K18 | L18: =-((K38+L38+K40+L40)/2)*'Forecasting Assumptions'!L18 | M18: =-((L38+M38+L40+M40)/2)*'Forecasting Assumptions'!M18 | N18: =-((M38+N38+M40+N40)/2)*'Forecasting Assumptions'!N18 | ... R18: =-((Q38+R38+Q40+R40)/2)*'Forecasting Assumptions'!R18
A19: EBIT | B19: =B17+B18 | C19: =C17+C18 | D19: =D17+D18 | E19: =E17+E18 | F19: =F17+F18 | G19: =G17+G18 | H19: =H17+H18 | I19: =I17+I18 | ... R19: =R17+R18
A20: Net Interest Expense | B20: =B90 | C20: =C90 | D20: =D90 | E20: =E90 | F20: =F90 | G20: =-((F44+G44+F49+G49)/2)*'Forecasting Assumptions'!G19 | H20: =-((G44+H44+G49+H49)/2)*'Forecasting Assumptions'!H19 | I20: =-((H44+I44+H49+I49)/2)*'Forecasting Assumptions'!I19 | J20: =-((I44+J44+I49+J49)/2)*'Forecasting Assumptions'!J19 | K20: =-((J44+K44+J49+K49)/2)*'Forecasting Assumptions'!K19 | L20: =-((K44+L44+K49+L49)/2)*'Forecasting Assumptions'!L19 | M20: =-((L44+M44+L49+M49)/2)*'Forecasting Assumptions'!M19 | N20: =-((M44+N44+M49+N49)/2)*'Forecasting Assumptions'!N19 | ... R20: =-((Q44+R44+Q49+R49)/2)*'Forecasting Assumptions'!R19
A21: Non-Operating Income (Loss) | B21: =B91 | C21: =C91 | D21: =D91 | E21: =E91 | F21: =F91 | G21: =G12*'Forecasting Assumptions'!G20 | H21: =H12*'Forecasting Assumptions'!H20 | I21: =I12*'Forecasting Assumptions'!I20 | J21: =J12*'Forecasting Assumptions'!J20 | K21: =K12*'Forecasting Assumptions'!K20 | L21: =L12*'Forecasting Assumptions'!L20 | M21: =M12*'Forecasting Assumptions'!M20 | N21: =N12*'Forecasting Assumptions'!N20 | ... R21: =R12*'Forecasting Assumptions'!R20
A22: EBT | B22: =B19+B20+B21 | C22: =C19+C20+C21 | D22: =D19+D20+D21 | E22: =E19+E20+E21 | F22: =F19+F20+F21 | G22: =G19+G20+G21 | H22: =H19+H20+H21 | I22: =I19+I20+I21 | ... R22: =R19+R20+R21
A23: Income Taxes | B23: =B92 | C23: =C92 | D23: =D92 | E23: =E92 | F23: =F92 | G23: =-G22*'Forecasting Assumptions'!G21 | H23: =-H22*'Forecasting Assumptions'!H21 | I23: =-I22*'Forecasting Assumptions'!I21 | J23: =-J22*'Forecasting Assumptions'!J21 | K23: =-K22*'Forecasting Assumptions'!K21 | L23: =-L22*'Forecasting Assumptions'!L21 | M23: =-M22*'Forecasting Assumptions'!M21 | N23: =-N22*'Forecasting Assumptions'!N21 | ... R23: =-R22*'Forecasting Assumptions'!R21
A24: Other Income (Loss) | B24: =B94 | C24: =C94 | D24: =D94 | E24: =E94 | F24: =F94 | G24: =G12*'Forecasting Assumptions'!G23 | H24: =H12*'Forecasting Assumptions'!H23 | I24: =I12*'Forecasting Assumptions'!I23 | J24: =J12*'Forecasting Assumptions'!J23 | K24: =K12*'Forecasting Assumptions'!K23 | L24: =L12*'Forecasting Assumptions'!L23 | M24: =M12*'Forecasting Assumptions'!M23 | N24: =N12*'Forecasting Assumptions'!N23 | ... R24: =R12*'Forecasting Assumptions'!R23
A25: Net Income Before Ext. Items | B25: =B22+B23+B24 | C25: =C22+C23+C24 | D25: =D22+D23+D24 | E25: =E22+E23+E24 | F25: =F22+F23+F24 | G25: =G22+G23+G24 | H25: =H22+H23+H24 | I25: =I22+I23+I24 | ... R25: =R22+R23+R24
A26: Ext. Items & Disc. Ops. | B26: =B95 | C26: =C95 | D26: =D95 | E26: =E95 | F26: =F95 | G26: =G12*'Forecasting Assumptions'!G24 | H26: =H12*'Forecasting Assumptions'!H24 | I26: =I12*'Forecasting Assumptions'!I24 | J26: =J12*'Forecasting Assumptions'!J24 | K26: =K12*'Forecasting Assumptions'!K24 | L26: =L12*'Forecasting Assumptions'!L24 | M26: =M12*'Forecasting Assumptions'!M24 | N26: =N12*'Forecasting Assumptions'!N24 | ... R26: =R12*'Forecasting Assumptions'!R24
A27: Noncontrolling Interest in Earnings | B27: =B93 | C27: =C93 | D27: =D93 | E27: =E93 | F27: =F93 | G27: =-(G22+G23)*'Forecasting Assumptions'!G22 | H27: =-(H22+H23)*'Forecasting Assumptions'!H22 | I27: =-(I22+I23)*'Forecasting Assumptions'!I22 | J27: =-(J22+J23)*'Forecasting Assumptions'!J22 | K27: =-(K22+K23)*'Forecasting Assumptions'!K22 | L27: =-(L22+L23)*'Forecasting Assumptions'!L22 | M27: =-(M22+M23)*'Forecasting Assumptions'!M22 | N27: =-(N22+N23)*'Forecasting Assumptions'!N22 | ... R27: =-(R22+R23)*'Forecasting Assumptions'!R22
A28: Preferred Dividends | B28: =B96 | C28: =C96 | D28: =D96 | E28: =E96 | F28: =F96 | G28: =-((G54+F54)/2)*'Forecasting Assumptions'!G25 | H28: =-((H54+G54)/2)*'Forecasting Assumptions'!H25 | I28: =-((I54+H54)/2)*'Forecasting Assumptions'!I25 | J28: =-((J54+I54)/2)*'Forecasting Assumptions'!J25 | K28: =-((K54+J54)/2)*'Forecasting Assumptions'!K25 | L28: =-((L54+K54)/2)*'Forecasting Assumptions'!L25 | M28: =-((M54+L54)/2)*'Forecasting Assumptions'!M25 | N28: =-((N54+M54)/2)*'Forecasting Assumptions'!N25 | ... R28: =-((R54+Q54)/2)*'Forecasting Assumptions'!R25
A29: Net Income (available to common) | B29: =B25+B26+B27+B28 | C29: =C25+C26+C27+C28 | D29: =D25+D26+D27+D28 | E29: =E25+E26+E27+E28 | F29: =F25+F26+F27+F28 | G29: =G25+G26+G27+G28 | H29: =H25+H26+H27+H28 | I29: =I25+I26+I27+I28 | ... R29: =R25+R26+R27+R28
B30: =IF(B13>0,"Error! -Exp?",IF(B15>0,"Error! -Exp?",IF(B16>0,"Error! -Exp?","")))
A31: Balance Sheet
A33: Operating Cash and Market. Sec. | B33: =B97 | C33: =C97 | D33: =D97 | E33: =E97 | F33: =F97 | G33: =G12*'Forecasting Assumptions'!G29 | H33: =H12*'Forecasting Assumptions'!H29 | I33: =I12*'Forecasting Assumptions'!I29 | J33: =J12*'Forecasting Assumptions'!J29 | K33: =K12*'Forecasting Assumptions'!K29 | L33: =L12*'Forecasting Assumptions'!L29 | M33: =M12*'Forecasting Assumptions'!M29 | N33: =N12*'Forecasting Assumptions'!N29 | ... R33: =R12*'Forecasting Assumptions'!R29
A34: Receivables | B34: =B98 | C34: =C98 | D34: =D98 | E34: =E98 | F34: =F98 | G34: =G12*'Forecasting Assumptions'!G30 | H34: =H12*'Forecasting Assumptions'!H30 | I34: =I12*'Forecasting Assumptions'!I30 | J34: =J12*'Forecasting Assumptions'!J30 | K34: =K12*'Forecasting Assumptions'!K30 | L34: =L12*'Forecasting Assumptions'!L30 | M34: =M12*'Forecasting Assumptions'!M30 | N34: =N12*'Forecasting Assumptions'!N30 | ... R34: =R12*'Forecasting Assumptions'!R30
A35: Inventories | B35: =B99 | C35: =C99 | D35: =D99 | E35: =E99 | F35: =F99 | G35: =-G13*'Forecasting Assumptions'!G31 | H35: =-H13*'Forecasting Assumptions'!H31 | I35: =-I13*'Forecasting Assumptions'!I31 | J35: =-J13*'Forecasting Assumptions'!J31 | K35: =-K13*'Forecasting Assumptions'!K31 | L35: =-L13*'Forecasting Assumptions'!L31 | M35: =-M13*'Forecasting Assumptions'!M31 | N35: =-N13*'Forecasting Assumptions'!N31 | ... R35: =-R13*'Forecasting Assumptions'!R31
A36: Other Current Assets | B36: =B100 | C36: =C100 | D36: =D100 | E36: =E100 | F36: =F100 | G36: =G12*'Forecasting Assumptions'!G32 | H36: =H12*'Forecasting Assumptions'!H32 | I36: =I12*'Forecasting Assumptions'!I32 | J36: =J12*'Forecasting Assumptions'!J32 | K36: =K12*'Forecasting Assumptions'!K32 | L36: =L12*'Forecasting Assumptions'!L32 | M36: =M12*'Forecasting Assumptions'!M32 | N36: =N12*'Forecasting Assumptions'!N32 | ... R36: =R12*'Forecasting Assumptions'!R32
A37: Total Current Assets | B37: =SUM(B33:B36) | C37: =SUM(C33:C36) | D37: =SUM(D33:D36) | E37: =SUM(E33:E36) | F37: =SUM(F33:F36) | G37: =SUM(G33:G36) | H37: =SUM(H33:H36) | I37: =SUM(I33:I36) | ... R37: =SUM(R33:R36)
A38: PP&E (Net) | B38: =B101 | C38: =C101 | D38: =D101 | E38: =E101 | F38: =F101 | G38: =G12*'Forecasting Assumptions'!G37 | H38: =H12*'Forecasting Assumptions'!H37 | I38: =I12*'Forecasting Assumptions'!I37 | J38: =J12*'Forecasting Assumptions'!J37 | K38: =K12*'Forecasting Assumptions'!K37 | L38: =L12*'Forecasting Assumptions'!L37 | M38: =M12*'Forecasting Assumptions'!M37 | N38: =N12*'Forecasting Assumptions'!N37 | ... R38: =R12*'Forecasting Assumptions'!R37
A39: Investments | B39: =B102 | C39: =C102 | D39: =D102 | E39: =E102 | F39: =F102 | G39: =G12*'Forecasting Assumptions'!G38 | H39: =H12*'Forecasting Assumptions'!H38 | I39: =I12*'Forecasting Assumptions'!I38 | J39: =J12*'Forecasting Assumptions'!J38 | K39: =K12*'Forecasting Assumptions'!K38 | L39: =L12*'Forecasting Assumptions'!L38 | M39: =M12*'Forecasting Assumptions'!M38 | N39: =N12*'Forecasting Assumptions'!N38 | ... R39: =R12*'Forecasting Assumptions'!R38
A40: Intangibles | B40: =B103 | C40: =C103 | D40: =D103 | E40: =E103 | F40: =F103 | G40: =G12*'Forecasting Assumptions'!G39 | H40: =H12*'Forecasting Assumptions'!H39 | I40: =I12*'Forecasting Assumptions'!I39 | J40: =J12*'Forecasting Assumptions'!J39 | K40: =K12*'Forecasting Assumptions'!K39 | L40: =L12*'Forecasting Assumptions'!L39 | M40: =M12*'Forecasting Assumptions'!M39 | N40: =N12*'Forecasting Assumptions'!N39 | ... R40: =R12*'Forecasting Assumptions'!R39
A41: Other Assets | B41: =B104 | C41: =C104 | D41: =D104 | E41: =E104 | F41: =F104 | G41: =G12*'Forecasting Assumptions'!G40 | H41: =H12*'Forecasting Assumptions'!H40 | I41: =I12*'Forecasting Assumptions'!I40 | J41: =J12*'Forecasting Assumptions'!J40 | K41: =K12*'Forecasting Assumptions'!K40 | L41: =L12*'Forecasting Assumptions'!L40 | M41: =M12*'Forecasting Assumptions'!M40 | N41: =N12*'Forecasting Assumptions'!N40 | ... R41: =R12*'Forecasting Assumptions'!R40
A42: Total Assets | B42: =SUM(B37:B41) | C42: =SUM(C37:C41) | D42: =SUM(D37:D41) | E42: =SUM(E37:E41) | F42: =SUM(F37:F41) | G42: =G37+G38+G39+G40+G41 | H42: =H37+H38+H39+H40+H41 | I42: =I37+I38+I39+I40+I41 | J42: =J37+J38+J39+J40+J41 | K42: =K37+K38+K39+K40+K41 | L42: =L37+L38+L39+L40+L41 | M42: =M37+M38+M39+M40+M41 | N42: =N37+N38+N39+N40+N41 | ... R42: =R37+R38+R39+R40+R41
A44: Current Debt | B44: =B105 | C44: =C105 | D44: =D105 | E44: =E105 | F44: =F105 | G44: =G42*'Forecasting Assumptions'!G45 | H44: =H42*'Forecasting Assumptions'!H45 | I44: =I42*'Forecasting Assumptions'!I45 | J44: =J42*'Forecasting Assumptions'!J45 | K44: =K42*'Forecasting Assumptions'!K45 | L44: =L42*'Forecasting Assumptions'!L45 | M44: =M42*'Forecasting Assumptions'!M45 | N44: =N42*'Forecasting Assumptions'!N45 | ... R44: =R42*'Forecasting Assumptions'!R45
A45: Accounts Payable | B45: =B106 | C45: =C106 | D45: =D106 | E45: =E106 | F45: =F106 | G45: =-G13*'Forecasting Assumptions'!G33 | H45: =-H13*'Forecasting Assumptions'!H33 | I45: =-I13*'Forecasting Assumptions'!I33 | J45: =-J13*'Forecasting Assumptions'!J33 | K45: =-K13*'Forecasting Assumptions'!K33 | L45: =-L13*'Forecasting Assumptions'!L33 | M45: =-M13*'Forecasting Assumptions'!M33 | N45: =-N13*'Forecasting Assumptions'!N33 | ... R45: =-R13*'Forecasting Assumptions'!R33
...

Sheet Ratio Analysis
A1: Ratio Analysis
A4: Company Name | B4: ='Financial Statements'!B4
B6: Actual | C6: Actual | D6: Actual | E6: Actual | F6: Actual | G6: Forecast | H6: Forecast | I6: Forecast | J6: Forecast | K6: Forecast | L6: Forecast | M6: Forecast | N6: Forecast | O6: Forecast | P6: Forecast | Q6: Forecast | R6: Forecast
A7: Fiscal Year End Date | B7: ='Financial Statements'!B8 | C7: ='Financial Statements'!C8 | D7: ='Financial Statements'!D8 | E7: ='Financial Statements'!E8 | F7: ='Financial Statements'!F8 | G7: ='Financial Statements'!G8 | H7: ='Financial Statements'!H8 | I7: ='Financial Statements'!I8 | ... R7: ='Financial Statements'!R8
A9: Annual Growth Rates
A10: Sales | C10: ='Financial Statements'!C12/'Financial Statements'!B12-1 | D10: ='Financial Statements'!D12/'Financial Statements'!C12-1 | E10: ='Financial Statements'!E12/'Financial Statements'!D12-1 | F10: ='Financial Statements'!F12/'Financial Statements'!E12-1 | G10: ='Financial Statements'!G12/'Financial Statements'!F12-1 | H10: ='Financial Statements'!H12/'Financial Statements'!G12-1 | I10: ='Financial Statements'!I12/'Financial Statements'!H12-1 | J10: ='Financial Statements'!J12/'Financial Statements'!I12-1 | ... R10: ='Financial Statements'!R12/'Financial Statements'!Q12-1
A11: Assets | C11: =IF('Financial Statements'!B42<=0,#N/A,'Financial Statements'!C42/'Financial Statements'!B42-1) | D11: =IF('Financial Statements'!C42<=0,#N/A,'Financial Statements'!D42/'Financial Statements'!C42-1) | E11: =IF('Financial Statements'!D42<=0,#N/A,'Financial Statements'!E42/'Financial Statements'!D42-1) | F11: =IF('Financial Statements'!E42<=0,#N/A,'Financial Statements'!F42/'Financial Statements'!E42-1) | G11: =IF('Financial Statements'!F42<=0,#N/A,'Financial Statements'!G42/'Financial Statements'!F42-1) | H11: =IF('Financial Statements'!G42<=0,#N/A,'Financial Statements'!H42/'Financial Statements'!G42-1) | I11: =IF('Financial Statements'!H42<=0,#N/A,'Financial Statements'!I42/'Financial Statements'!H42-1) | J11: =IF('Financial Statements'!I42<=0,#N/A,'Financial Statements'!J42/'Financial Statements'!I42-1) | ... R11: =IF('Financial Statements'!Q42<=0,#N/A,'Financial Statements'!R42/'Financial Statements'!Q42-1)
A12: Common Equity | C12: =IF('Financial Statements'!B57<=0,#N/A,'Financial Statements'!C57/'Financial Statements'!B57-1) | D12: =IF('Financial Statements'!C57<=0,#N/A,'Financial Statements'!D57/'Financial Statements'!C57-1) | E12: =IF('Financial Statements'!D57<=0,#N/A,'Financial Statements'!E57/'Financial Statements'!D57-1) | F12: =IF('Financial Statements'!E57<=0,#N/A,'Financial Statements'!F57/'Financial Statements'!E57-1) | G12: =IF('Financial Statements'!F57<=0,#N/A,'Financial Statements'!G57/'Financial Statements'!F57-1) | H12: =IF('Financial Statements'!G57<=0,#N/A,'Financial Statements'!H57/'Financial Statements'!G57-1) | I12: =IF('Financial Statements'!H57<=0,#N/A,'Financial Statements'!I57/'Financial Statements'!H57-1) | J12: =IF('Financial Statements'!I57<=0,#N/A,'Financial Statements'!J57/'Financial Statements'!I57-1) | ... R12: =IF('Financial Statements'!Q57<=0,#N/A,'Financial Statements'!R57/'Financial Statements'!Q57-1)
A13: Earnings | C13: =IF('Financial Statements'!B29<=0,#N/A,'Financial Statements'!C29/'Financial Statements'!B29-1) | D13: =IF('Financial Statements'!C29<=0,#N/A,'Financial Statements'!D29/'Financial Statements'!C29-1) | E13: =IF('Financial Statements'!D29<=0,#N/A,'Financial Statements'!E29/'Financial Statements'!D29-1) | F13: =IF('Financial Statements'!E29<=0,#N/A,'Financial Statements'!F29/'Financial Statements'!E29-1) | G13: =IF('Financial Statements'!F29<=0,#N/A,'Financial Statements'!G29/'Financial Statements'!F29-1) | H13: =IF('Financial Statements'!G29<=0,#N/A,'Financial Statements'!H29/'Financial Statements'!G29-1) | I13: =IF('Financial Statements'!H29<=0,#N/A,'Financial Statements'!I29/'Financial Statements'!H29-1) | J13: =IF('Financial Statements'!I29<=0,#N/A,'Financial Statements'!J29/'Financial Statements'!I29-1) | ... R13: =IF('Financial Statements'!Q29<=0,#N/A,'Financial Statements'!R29/'Financial Statements'!Q29-1)
A14: Free Cash Flow to Investors | D14: =IF('Cash Flow Analysis'!B116<=0,#N/A,'Cash Flow Analysis'!C116/'Cash Flow Analysis'!B116-1) | E14: =IF('Cash Flow Analysis'!C116<=0,#N/A,'Cash Flow Analysis'!D116/'Cash Flow Analysis'!C116-1) | F14: =IF('Cash Flow Analysis'!D116<=0,#N/A,'Cash Flow Analysis'!E116/'Cash Flow Analysis'!D116-1) | G14: =IF('Cash Flow Analysis'!E116<=0,#N/A,'Cash Flow Analysis'!F116/'Cash Flow Analysis'!E116-1) | H14: =IF('Cash Flow Analysis'!F116<=0,#N/A,'Cash Flow Analysis'!G116/'Cash Flow Analysis'!F116-1) | I14: =IF('Cash Flow Analysis'!G116<=0,#N/A,'Cash Flow Analysis'!H116/'Cash Flow Analysis'!G116-1) | J14: =IF('Cash Flow Analysis'!H116<=0,#N/A,'Cash Flow Analysis'!I116/'Cash Flow Analysis'!H116-1) | K14: =IF('Cash Flow Analysis'!I116<=0,#N/A,'Cash Flow Analysis'!J116/'Cash Flow Analysis'!I116-1) | ... R14: =IF('Cash Flow Analysis'!P116<=0,#N/A,'Cash Flow Analysis'!Q116/'Cash Flow Analysis'!P116-1)
A15: Sustainable Growth Rate | D15: =D19*(1-'Forecasting Assumptions'!D49) | E15: =E19*(1-'Forecasting Assumptions'!E49) | F15: =F19*(1-'Forecasting Assumptions'!F49) | G15: =G19*(1-'Forecasting Assumptions'!G49) | H15: =H19*(1-'Forecasting Assumptions'!H49) | I15: =I19*(1-'Forecasting Assumptions'!I49) | J15: =J19*(1-'Forecasting Assumptions'!J49) | K15: =K19*(1-'Forecasting Assumptions'!K49) | ... R15: =R19*(1-'Forecasting Assumptions'!R49)
A18: Profitability
A19: Return on Equity | C19: ='Financial Statements'!C73/(('Financial Statements'!B77+'Financial Statements'!C77)/2) | D19: ='Financial Statements'!D73/(('Financial Statements'!C77+'Financial Statements'!D77)/2) | E19: ='Financial Statements'!E73/(('Financial Statements'!D77+'Financial Statements'!E77)/2) | F19: ='Financial Statements'!F73/(('Financial Statements'!E77+'Financial Statements'!F77)/2) | G19: ='Financial Statements'!G73/(('Financial Statements'!F77+'Financial Statements'!G77)/2) | H19: ='Financial Statements'!H73/(('Financial Statements'!G77+'Financial Statements'!H77)/2) | I19: ='Financial Statements'!I73/(('Financial Statements'!H77+'Financial Statements'!I77)/2) | J19: ='Financial Statements'!J73/(('Financial Statements'!I77+'Financial Statements'!J77)/2) | ... R19: ='Financial Statements'!R73/(('Financial Statements'!Q77+'Financial Statements'!R77)/2)
A20: Return on Equity (b4 non-recurring) | C20: =('Financial Statements'!C29-'Financial Statements'!C26-'Financial Statements'!C24-((IF('Financial Statements'!C22=0,0,('Financial Statements'!C22+'Financial Statements'!C23)/'Financial Statements'!C22))*'Financial Statements'!C21))/(('Financial Statements'!B77+'Financial Statements'!C77)/2) | D20: =('Financial Statements'!D29-'Financial Statements'!D26-'Financial Statements'!D24-((IF('Financial Statements'!D22=0,0,('Financial Statements'!D22+'Financial Statements'!D23)/'Financial Statements'!D22))*'Financial Statements'!D21))/(('Financial Statements'!C77+'Financial Statements'!D77)/2) | E20: =('Financial Statements'!E29-'Financial Statements'!E26-'Financial Statements'!E24-((IF('Financial Statements'!E22=0,0,('Financial Statements'!E22+'Financial Statements'!E23)/'Financial Statements'!E22))*'Financial Statements'!E21))/(('Financial Statements'!D77+'Financial Statements'!E77)/2) | F20: =('Financial Statements'!F29-'Financial Statements'!F26-'Financial Statements'!F24-((IF('Financial Statements'!F22=0,0,('Financial Statements'!F22+'Financial Statements'!F23)/'Financial Statements'!F22))*'Financial Statements'!F21))/(('Financial Statements'!E77+'Financial Statements'!F77)/2) | G20: =('Financial Statements'!G29-'Financial Statements'!G26-'Financial Statements'!G24-((IF('Financial Statements'!G22=0,0,('Financial Statements'!G22+'Financial Statements'!G23)/'Financial Statements'!G22))*'Financial Statements'!G21))/(('Financial Statements'!F77+'Financial Statements'!G77)/2) | H20: =('Financial Statements'!H29-'Financial Statements'!H26-'Financial Statements'!H24-((IF('Financial Statements'!H22=0,0,('Financial Statements'!H22+'Financial Statements'!H23)/'Financial Statements'!H22))*'Financial Statements'!H21))/(('Financial Statements'!G77+'Financial Statements'!H77)/2) | I20: =('Financial Statements'!I29-'Financial Statements'!I26-'Financial Statements'!I24-((IF('Financial Statements'!I22=0,0,('Financial Statements'!I22+'Financial Statements'!I23)/'Financial Statements'!I22))*'Financial Statements'!I21))/(('Financial Statements'!H77+'Financial Statements'!I77)/2) | J20: =('Financial Statements'!J29-'Financial Statements'!J26-'Financial Statements'!J24-((IF('Financial Statements'!J22=0,0,('Financial Statements'!J22+'Financial Statements'!J23)/'Financial Statements'!J22))*'Financial Statements'!J21))/(('Financial Statements'!I77+'Financial Statements'!J77)/2) | ... R20: =('Financial Statements'!R29-'Financial Statements'!R26-'Financial Statements'!R24-((IF('Financial Statements'!R22=0,0,('Financial Statements'!R22+'Financial Statements'!R23)/'Financial Statements'!R22))*'Financial Statements'!R21))/(('Financial Statements'!Q77+'Financial Statements'!R77)/2)
A21: Return on Net Operating Assets | C21: ='Financial Statements'!C71/(('Financial Statements'!B75+'Financial Statements'!C75)/2) | D21: ='Financial Statements'!D71/(('Financial Statements'!C75+'Financial Statements'!D75)/2) | E21: ='Financial Statements'!E71/(('Financial Statements'!D75+'Financial Statements'!E75)/2) | F21: ='Financial Statements'!F71/(('Financial Statements'!E75+'Financial Statements'!F75)/2) | G21: ='Financial Statements'!G71/(('Financial Statements'!F75+'Financial Statements'!G75)/2) | H21: ='Financial Statements'!H71/(('Financial Statements'!G75+'Financial Statements'!H75)/2) | I21: ='Financial Statements'!I71/(('Financial Statements'!H75+'Financial Statements'!I75)/2) | J21: ='Financial Statements'!J71/(('Financial Statements'!I75+'Financial Statements'!J75)/2) | ... R21: ='Financial Statements'!R71/(('Financial Statements'!Q75+'Financial Statements'!R75)/2)
A23: Basic Dupont Model
A24: Net Profit Margin | B24: ='Financial Statements'!B29/'Financial Statements'!B12 | C24: ='Financial Statements'!C29/'Financial Statements'!C12 | D24: ='Financial Statements'!D29/'Financial Statements'!D12 | E24: ='Financial Statements'!E29/'Financial Statements'!E12 | F24: ='Financial Statements'!F29/'Financial Statements'!F12 | G24: ='Financial Statements'!G29/'Financial Statements'!G12 | H24: ='Financial Statements'!H29/'Financial Statements'!H12 | I24: ='Financial Statements'!I29/'Financial Statements'!I12 | ... R24: ='Financial Statements'!R29/'Financial Statements'!R12
A25: x Total Asset Turnover | C25: ='Financial Statements'!C12/(('Financial Statements'!B42+'Financial Statements'!C42)/2) | D25: ='Financial Statements'!D12/(('Financial Statements'!C42+'Financial Statements'!D42)/2) | E25: ='Financial Statements'!E12/(('Financial Statements'!D42+'Financial Statements'!E42)/2) | F25: ='Financial Statements'!F12/(('Financial Statements'!E42+'Financial Statements'!F42)/2) | G25: ='Financial Statements'!G12/(('Financial Statements'!F42+'Financial Statements'!G42)/2) | H25: ='Financial Statements'!H12/(('Financial Statements'!G42+'Financial Statements'!H42)/2) | I25: ='Financial Statements'!I12/(('Financial Statements'!H42+'Financial Statements'!I42)/2) | J25: ='Financial Statements'!J12/(('Financial Statements'!I42+'Financial Statements'!J42)/2) | ... R25: ='Financial Statements'!R12/(('Financial Statements'!Q42+'Financial Statements'!R42)/2)
A26: x Total Leverage | C26: =('Financial Statements'!B58+'Financial Statements'!C58)/('Financial Statements'!B57+'Financial Statements'!C57) | D26: =('Financial Statements'!C58+'Financial Statements'!D58)/('Financial Statements'!C57+'Financial Statements'!D57) | E26: =('Financial Statements'!D58+'Financial Statements'!E58)/('Financial Statements'!D57+'Financial Statements'!E57) | F26: =('Financial Statements'!E58+'Financial Statements'!F58)/('Financial Statements'!E57+'Financial Statements'!F57) | G26: =('Financial Statements'!F58+'Financial Statements'!G58)/('Financial Statements'!F57+'Financial Statements'!G57) | H26: =('Financial Statements'!G58+'Financial Statements'!H58)/('Financial Statements'!G57+'Financial Statements'!H57) | I26: =('Financial Statements'!H58+'Financial Statements'!I58)/('Financial Statements'!H57+'Financial Statements'!I57) | J26: =('Financial Statements'!I58+'Financial Statements'!J58)/('Financial Statements'!I57+'Financial Statements'!J57) | ... R26: =('Financial Statements'!Q58+'Financial Statements'!R58)/('Financial Statements'!Q57+'Financial Statements'!R57)
A27: = Return on Equity | C27: =C24*C25*C26 | D27: =D24*D25*D26 | E27: =E24*E25*E26 | F27: =F24*F25*F26 | G27: =G24*G25*G26 | H27: =H24*H25*H26 | I27: =I24*I25*I26 | J27: =J24*J25*J26 | ... R27: =R24*R25*R26
A29: Advanced Dupont Model
A30: Net Operating Margin | B30: ='Financial Statements'!B71/'Financial Statements'!B12 | C30: ='Financial Statements'!C71/'Financial Statements'!C12 | D30: ='Financial Statements'!D71/'Financial Statements'!D12 | E30: ='Financial Statements'!E71/'Financial Statements'!E12 | F30: ='Financial Statements'!F71/'Financial Statements'!F12 | G30: ='Financial Statements'!G71/'Financial Statements'!G12 | H30: ='Financial Statements'!H71/'Financial Statements'!H12 | I30: ='Financial Statements'!I71/'Financial Statements'!I12 | ... R30: ='Financial Statements'!R71/'Financial Statements'!R12
A31: x Net Operating Asset Turnover | C31: ='Financial Statements'!C12/(('Financial Statements'!B75+'Financial Statements'!C75)/2) | D31: ='Financial Statements'!D12/(('Financial Statements'!C75+'Financial Statements'!D75)/2) | E31: ='Financial Statements'!E12/(('Financial Statements'!D75+'Financial Statements'!E75)/2) | F31: ='Financial Statements'!F12/(('Financial Statements'!E75+'Financial Statements'!F75)/2) | G31: ='Financial Statements'!G12/(('Financial Statements'!F75+'Financial Statements'!G75)/2) | H31: ='Financial Statements'!H12/(('Financial Statements'!G75+'Financial Statements'!H75)/2) | I31: ='Financial Statements'!I12/(('Financial Statements'!H75+'Financial Statements'!I75)/2) | J31: ='Financial Statements'!J12/(('Financial Statements'!I75+'Financial Statements'!J75)/2) | ... R31: ='Financial Statements'!R12/(('Financial Statements'!Q75+'Financial Statements'!R75)/2)
A32: = Return on Net Operating Assets | C32: =C30*C31 | D32: =D30*D31 | E32: =E30*E31 | F32: =F30*F31 | G32: =G30*G31 | H32: =H30*H31 | I32: =I30*I31 | J32: =J30*J31 | ... R32: =R30*R31
A33: Net Borrowing Cost (NBC) | C33: =-'Financial Statements'!C72/(('Financial Statements'!B76+'Financial Statements'!C76)/2) | D33: =-'Financial Statements'!D72/(('Financial Statements'!C76+'Financial Statements'!D76)/2) | E33: =-'Financial Statements'!E72/(('Financial Statements'!D76+'Financial Statements'!E76)/2) | F33: =-'Financial Statements'!F72/(('Financial Statements'!E76+'Financial Statements'!F76)/2) | G33: =-'Financial Statements'!G72/(('Financial Statements'!F76+'Financial Statements'!G76)/2) | H33: =-'Financial Statements'!H72/(('Financial Statements'!G76+'Financial Statements'!H76)/2) | I33: =-'Financial Statements'!I72/(('Financial Statements'!H76+'Financial Statements'!I76)/2) | J33: =-'Financial Statements'!J72/(('Financial Statements'!I76+'Financial Statements'!J76)/2) | ... R33: =-'Financial Statements'!R72/(('Financial Statements'!Q76+'Financial Statements'!R76)/2)
A34: Spread (RNOA - NBC) | C34: =C32-C33 | D34: =D32-D33 | E34: =E32-E33 | F34: =F32-F33 | G34: =G32-G33 | H34: =H32-H33 | I34: =I32-I33 | J34: =J32-J33 | ... R34: =R32-R33
A35: Financial Leverage (LEV) | C35: =('Financial Statements'!B76+'Financial Statements'!C76)/('Financial Statements'!B77+'Financial Statements'!C77) | D35: =('Financial Statements'!C76+'Financial Statements'!D76)/('Financial Statements'!C77+'Financial Statements'!D77) | E35: =('Financial Statements'!D76+'Financial Statements'!E76)/('Financial Statements'!D77+'Financial Statements'!E77) | F35: =('Financial Statements'!E76+'Financial Statements'!F76)/('Financial Statements'!E77+'Financial Statements'!F77) | G35: =('Financial Statements'!F76+'Financial Statements'!G76)/('Financial Statements'!F77+'Financial Statements'!G77) | H35: =('Financial Statements'!G76+'Financial Statements'!H76)/('Financial Statements'!G77+'Financial Statements'!H77) | I35: =('Financial Statements'!H76+'Financial Statements'!I76)/('Financial Statements'!H77+'Financial Statements'!I77) | J35: =('Financial Statements'!I76+'Financial Statements'!J76)/('Financial Statements'!I77+'Financial Statements'!J77) | ... R35: =('Financial Statements'!Q76+'Financial Statements'!R76)/('Financial Statements'!Q77+'Financial Statements'!R77)
A36: ROE = RNOA + LEV*Spread | C36: =C32+(C35*C34) | D36: =D32+(D35*D34) | E36: =E32+(E35*E34) | F36: =F32+(F35*F34) | G36: =G32+(G35*G34) | H36: =H32+(H35*H34) | I36: =I32+(I35*I34) | J36: =J32+(J35*J34) | ... R36: =R32+(R35*R34)
A39: Margin Analysis
A40: Gross Margin | B40: ='Financial Statements'!B14/'Financial Statements'!B12 | C40: ='Financial Statements'!C14/'Financial Statements'!C12 | D40: ='Financial Statements'!D14/'Financial Statements'!D12 | E40: ='Financial Statements'!E14/'Financial Statements'!E12 | F40: ='Financial Statements'!F14/'Financial Statements'!F12 | G40: ='Financial Statements'!G14/'Financial Statements'!G12 | H40: ='Financial Statements'!H14/'Financial Statements'!H12 | I40: ='Financial Statements'!I14/'Financial Statements'!I12 | ... R40: ='Financial Statements'!R14/'Financial Statements'!R12
A41: EBITDA Margin | B41: ='Financial Statements'!B17/'Financial Statements'!B12 | C41: ='Financial Statements'!C17/'Financial Statements'!C12 | D41: ='Financial Statements'!D17/'Financial Statements'!D12 | E41: ='Financial Statements'!E17/'Financial Statements'!E12 | F41: ='Financial Statements'!F17/'Financial Statements'!F12 | G41: ='Financial Statements'!G17/'Financial Statements'!G12 | H41: ='Financial Statements'!H17/'Financial Statements'!H12 | I41: ='Financial Statements'!I17/'Financial Statements'!I12 | ... R41: ='Financial Statements'!R17/'Financial Statements'!R12
A42: EBIT Margin | B42: ='Financial Statements'!B19/'Financial Statements'!B12 | C42: ='Financial Statements'!C19/'Financial Statements'!C12 | D42: ='Financial Statements'!D19/'Financial Statements'!D12 | E42: ='Financial Statements'!E19/'Financial Statements'!E12 | F42: ='Financial Statements'!F19/'Financial Statements'!F12 | G42: ='Financial Statements'!G19/'Financial Statements'!G12 | H42: ='Financial Statements'!H19/'Financial Statements'!H12 | I42: ='Financial Statements'!I19/'Financial Statements'!I12 | ... R42: ='Financial Statements'!R19/'Financial Statements'!R12
A43: Net Operating Margin (b4 non-rec.) | B43: =('Financial Statements'!B71-'Financial Statements'!B21*(1-'Forecasting Assumptions'!B21)-'Financial Statements'!B26-'Financial Statements'!B24)/'Financial Statements'!B12 | C43: =('Financial Statements'!C71-'Financial Statements'!C21*(1-'Forecasting Assumptions'!C21)-'Financial Statements'!C26-'Financial Statements'!C24)/'Financial Statements'!C12 | D43: =('Financial Statements'!D71-'Financial Statements'!D21*(1-'Forecasting Assumptions'!D21)-'Financial Statements'!D26-'Financial Statements'!D24)/'Financial Statements'!D12 | E43: =('Financial Statements'!E71-'Financial Statements'!E21*(1-'Forecasting Assumptions'!E21)-'Financial Statements'!E26-'Financial Statements'!E24)/'Financial Statements'!E12 | F43: =('Financial Statements'!F71-'Financial Statements'!F21*(1-'Forecasting Assumptions'!F21)-'Financial Statements'!F26-'Financial Statements'!F24)/'Financial Statements'!F12 | G43: =('Financial Statements'!G71-'Financial Statements'!G21*(1-'Forecasting Assumptions'!G21)-'Financial Statements'!G26-'Financial Statements'!G24)/'Financial Statements'!G12 | H43: =('Financial Statements'!H71-'Financial Statements'!H21*(1-'Forecasting Assumptions'!H21)-'Financial Statements'!H26-'Financial Statements'!H24)/'Financial Statements'!H12 | I43: =('Financial Statements'!I71-'Financial Statements'!I21*(1-'Forecasting Assumptions'!I21)-'Financial Statements'!I26-'Financial Statements'!I24)/'Financial Statements'!I12 | ... R43: =('Financial Statements'!R71-'Financial Statements'!R21*(1-'Forecasting Assumptions'!R21)-'Financial Statements'!R26-'Financial Statements'!R24)/'Financial Statements'!R12
A44: Net Operating Margin | B44: ='Financial Statements'!B71/'Financial Statements'!B12 | C44: ='Financial Statements'!C71/'Financial Statements'!C12 | D44: ='Financial Statements'!D71/'Financial Statements'!D12 | E44: ='Financial Statements'!E71/'Financial Statements'!E12 | F44: ='Financial Statements'!F71/'Financial Statements'!F12 | G44: ='Financial Statements'!G71/'Financial Statements'!G12 | H44: ='Financial Statements'!H71/'Financial Statements'!H12 | I44: ='Financial Statements'!I71/'Financial Statements'!I12 | ... R44: ='Financial Statements'!R71/'Financial Statements'!R12
A46: Turnover Analysis
A47: Net Operating Asset Turnover | C47: ='Financial Statements'!C12/(('Financial Statements'!C75+'Financial Statements'!B75)/2) | D47: ='Financial Statements'!D12/(('Financial Statements'!D75+'Financial Statements'!C75)/2) | E47: ='Financial Statements'!E12/(('Financial Statements'!E75+'Financial Statements'!D75)/2) | F47: ='Financial Statements'!F12/(('Financial Statements'!F75+'Financial Statements'!E75)/2) | G47: ='Financial Statements'!G12/(('Financial Statements'!G75+'Financial Statements'!F75)/2) | H47: ='Financial Statements'!H12/(('Financial Statements'!H75+'Financial Statements'!G75)/2) | I47: ='Financial Statements'!I12/(('Financial Statements'!I75+'Financial Statements'!H75)/2) | J47: ='Financial Statements'!J12/(('Financial Statements'!J75+'Financial Statements'!I75)/2) | ... R47: ='Financial Statements'!R12/(('Financial Statements'!R75+'Financial Statements'!Q75)/2)
A48: Net Working Capital Turnover | C48: ='Financial Statements'!C12/(('Financial Statements'!B37-'Financial Statements'!B48+'Financial Statements'!B44+'Financial Statements'!C37-'Financial Statements'!C48+'Financial Statements'!C44)/2) | D48: ='Financial Statements'!D12/(('Financial Statements'!C37-'Financial Statements'!C48+'Financial Statements'!C44+'Financial Statements'!D37-'Financial Statements'!D48+'Financial Statements'!D44)/2) | E48: ='Financial Statements'!E12/(('Financial Statements'!D37-'Financial Statements'!D48+'Financial Statements'!D44+'Financial Statements'!E37-'Financial Statements'!E48+'Financial Statements'!E44)/2) | F48: ='Financial Statements'!F12/(('Financial Statements'!E37-'Financial Statements'!E48+'Financial Statements'!E44+'Financial Statements'!F37-'Financial Statements'!F48+'Financial Statements'!F44)/2) | G48: ='Financial Statements'!G12/(('Financial Statements'!F37-'Financial Statements'!F48+'Financial Statements'!F44+'Financial Statements'!G37-'Financial Statements'!G48+'Financial Statements'!G44)/2) | H48: ='Financial Statements'!H12/(('Financial Statements'!G37-'Financial Statements'!G48+'Financial Statements'!G44+'Financial Statements'!H37-'Financial Statements'!H48+'Financial Statements'!H44)/2) | I48: ='Financial Statements'!I12/(('Financial Statements'!H37-'Financial Statements'!H48+'Financial Statements'!H44+'Financial Statements'!I37-'Financial Statements'!I48+'Financial Statements'!I44)/2) | J48: ='Financial Statements'!J12/(('Financial Statements'!I37-'Financial Statements'!I48+'Financial Statements'!I44+'Financial Statements'!J37-'Financial Statements'!J48+'Financial Statements'!J44)/2) | ... R48: ='Financial Statements'!R12/(('Financial Statements'!Q37-'Financial Statements'!Q48+'Financial Statements'!Q44+'Financial Statements'!R37-'Financial Statements'!R48+'Financial Statements'!R44)/2)
A49: Avge Days to Collect Receivables | C49: =365*((('Financial Statements'!B34+'Financial Statements'!C34)/2)/'Financial Statements'!C12) | D49: =365*((('Financial Statements'!C34+'Financial Statements'!D34)/2)/'Financial Statements'!D12) | E49: =365*((('Financial Statements'!D34+'Financial Statements'!E34)/2)/'Financial Statements'!E12) | F49: =365*((('Financial Statements'!E34+'Financial Statements'!F34)/2)/'Financial Statements'!F12) | G49: =365*((('Financial Statements'!F34+'Financial Statements'!G34)/2)/'Financial Statements'!G12) | H49: =365*((('Financial Statements'!G34+'Financial Statements'!H34)/2)/'Financial Statements'!H12) | I49: =365*((('Financial Statements'!H34+'Financial Statements'!I34)/2)/'Financial Statements'!I12) | J49: =365*((('Financial Statements'!I34+'Financial Statements'!J34)/2)/'Financial Statements'!J12) | ... R49: =365*((('Financial Statements'!Q34+'Financial Statements'!R34)/2)/'Financial Statements'!R12)
A50: Avge Inventory Holding Period | C50: =-365*((('Financial Statements'!B35+'Financial Statements'!C35)/2)/'Financial Statements'!C13) | D50: =-365*((('Financial Statements'!C35+'Financial Statements'!D35)/2)/'Financial Statements'!D13) | E50: =-365*((('Financial Statements'!D35+'Financial Statements'!E35)/2)/'Financial Statements'!E13) | F50: =-365*((('Financial Statements'!E35+'Financial Statements'!F35)/2)/'Financial Statements'!F13) | G50: =-365*((('Financial Statements'!F35+'Financial Statements'!G35)/2)/'Financial Statements'!G13) | H50: =-365*((('Financial Statements'!G35+'Financial Statements'!H35)/2)/'Financial Statements'!H13) | I50: =-365*((('Financial Statements'!H35+'Financial Statements'!I35)/2)/'Financial Statements'!I13) | J50: =-365*((('Financial Statements'!I35+'Financial Statements'!J35)/2)/'Financial Statements'!J13) | ... R50: =-365*((('Financial Statements'!Q35+'Financial Statements'!R35)/2)/'Financial Statements'!R13)
A51: Avge Days to Pay Payables | C51: =365*((('Financial Statements'!B45+'Financial Statements'!C45)/2)/(-'Financial Statements'!C13+'Financial Statements'!C35-'Financial Statements'!B35)) | D51: =365*((('Financial Statements'!C45+'Financial Statements'!D45)/2)/(-'Financial Statements'!D13+'Financial Statements'!D35-'Financial Statements'!C35)) | E51: =365*((('Financial Statements'!D45+'Financial Statements'!E45)/2)/(-'Financial Statements'!E13+'Financial Statements'!E35-'Financial Statements'!D35)) | F51: =365*((('Financial Statements'!E45+'Financial Statements'!F45)/2)/(-'Financial Statements'!F13+'Financial Statements'!F35-'Financial Statements'!E35)) | G51: =365*((('Financial Statements'!F45+'Financial Statements'!G45)/2)/(-'Financial Statements'!G13+'Financial Statements'!G35-'Financial Statements'!F35)) | H51: =365*((('Financial Statements'!G45+'Financial Statements'!H45)/2)/(-'Financial Statements'!H13+'Financial Statements'!H35-'Financial Statements'!G35)) | I51: =365*((('Financial Statements'!H45+'Financial Statements'!I45)/2)/(-'Financial Statements'!I13+'Financial Statements'!I35-'Financial Statements'!H35)) | J51: =365*((('Financial Statements'!I45+'Financial Statements'!J45)/2)/(-'Financial Statements'!J13+'Financial Statements'!J35-'Financial Statements'!I35)) | ... R51: =365*((('Financial Statements'!Q45+'Financial Statements'!R45)/2)/(-'Financial Statements'!R13+'Financial Statements'!R35-'Financial Statements'!Q35))
...

Sheet Cash Flow Analysis
A1: Cash Flow Analysis | B1: ($000)
A4: Company Name | B4: ='Financial Statements'!B4
B6: Actual | C6: Actual | D6: Actual | E6: Actual | F6: Forecast | G6: Forecast | H6: Forecast | I6: Forecast | J6: Forecast | K6: Forecast | L6: Forecast | M6: Forecast | N6: Forecast | O6: Forecast | P6: Forecast | Q6: Forecast
A7: Fiscal Year End Date | B7: ='Financial Statements'!C8 | C7: ='Financial Statements'!D8 | D7: ='Financial Statements'!E8 | E7: ='Financial Statements'!F8 | F7: ='Financial Statements'!G8 | G7: ='Financial Statements'!H8 | H7: ='Financial Statements'!I8 | I7: ='Financial Statements'!J8 | ... Q7: ='Financial Statements'!R8
A8: Pro Forma Statement of Cash Flows
A10: Operating:
A11: Net Income | B11: ='Financial Statements'!C29 | C11: ='Financial Statements'!D29 | D11: ='Financial Statements'!E29 | E11: ='Financial Statements'!F29 | F11: ='Financial Statements'!G29 | G11: ='Financial Statements'!H29 | H11: ='Financial Statements'!I29 | I11: ='Financial Statements'!J29 | ... Q11: ='Financial Statements'!R29
A12: +Depreciation & Amortization | B12: =-'Financial Statements'!C18 | C12: =-'Financial Statements'!D18 | D12: =-'Financial Statements'!E18 | E12: =-'Financial Statements'!F18 | F12: =-'Financial Statements'!G18 | G12: =-'Financial Statements'!H18 | H12: =-'Financial Statements'!I18 | I12: =-'Financial Statements'!J18 | ... Q12: =-'Financial Statements'!R18
A13: +Increase in Deferred Taxes | B13: ='Financial Statements'!C51-'Financial Statements'!B51 | C13: ='Financial Statements'!D51-'Financial Statements'!C51 | D13: ='Financial Statements'!E51-'Financial Statements'!D51 | E13: ='Financial Statements'!F51-'Financial Statements'!E51 | F13: ='Financial Statements'!G51-'Financial Statements'!F51 | G13: ='Financial Statements'!H51-'Financial Statements'!G51 | H13: ='Financial Statements'!I51-'Financial Statements'!H51 | I13: ='Financial Statements'!J51-'Financial Statements'!I51 | ... Q13: ='Financial Statements'!R51-'Financial Statements'!Q51
A14: +Increase in Other Liabilities | B14: ='Financial Statements'!C50-'Financial Statements'!B50 | C14: ='Financial Statements'!D50-'Financial Statements'!C50 | D14: ='Financial Statements'!E50-'Financial Statements'!D50 | E14: ='Financial Statements'!F50-'Financial Statements'!E50 | F14: ='Financial Statements'!G50-'Financial Statements'!F50 | G14: ='Financial Statements'!H50-'Financial Statements'!G50 | H14: ='Financial Statements'!I50-'Financial Statements'!H50 | I14: ='Financial Statements'!J50-'Financial Statements'!I50 | ... Q14: ='Financial Statements'!R50-'Financial Statements'!Q50
A15: +Noncontrolling Interest in Earnings | B15: =-'Financial Statements'!C27 | C15: =-'Financial Statements'!D27 | D15: =-'Financial Statements'!E27 | E15: =-'Financial Statements'!F27 | F15: =-'Financial Statements'!G27 | G15: =-'Financial Statements'!H27 | H15: =-'Financial Statements'!I27 | I15: =-'Financial Statements'!J27 | ... Q15: =-'Financial Statements'!R27
A16: +Preferred Dividends | B16: =-'Financial Statements'!C28 | C16: =-'Financial Statements'!D28 | D16: =-'Financial Statements'!E28 | E16: =-'Financial Statements'!F28 | F16: =-'Financial Statements'!G28 | G16: =-'Financial Statements'!H28 | H16: =-'Financial Statements'!I28 | I16: =-'Financial Statements'!J28 | ... Q16: =-'Financial Statements'!R28
A17: =Funds From Operations | B17: =B11+B12+B13+B14+B15+B16 | C17: =C11+C12+C13+C14+C15+C16 | D17: =D11+D12+D13+D14+D15+D16 | E17: =E11+E12+E13+E14+E15+E16 | F17: =F11+F12+F13+F14+F15+F16 | G17: =G11+G12+G13+G14+G15+G16 | H17: =H11+H12+H13+H14+H15+H16 | I17: =I11+I12+I13+I14+I15+I16 | ... Q17: =Q11+Q12+Q13+Q14+Q15+Q16
A18: -Increase in Receivables | B18: =-('Financial Statements'!C34-'Financial Statements'!B34) | C18: =-('Financial Statements'!D34-'Financial Statements'!C34) | D18: =-('Financial Statements'!E34-'Financial Statements'!D34) | E18: =-('Financial Statements'!F34-'Financial Statements'!E34) | F18: =-('Financial Statements'!G34-'Financial Statements'!F34) | G18: =-('Financial Statements'!H34-'Financial Statements'!G34) | H18: =-('Financial Statements'!I34-'Financial Statements'!H34) | I18: =-('Financial Statements'!J34-'Financial Statements'!I34) | ... Q18: =-('Financial Statements'!R34-'Financial Statements'!Q34)
A19: -Increase in Inventory | B19: =-('Financial Statements'!C35-'Financial Statements'!B35) | C19: =-('Financial Statements'!D35-'Financial Statements'!C35) | D19: =-('Financial Statements'!E35-'Financial Statements'!D35) | E19: =-('Financial Statements'!F35-'Financial Statements'!E35) | F19: =-('Financial Statements'!G35-'Financial Statements'!F35) | G19: =-('Financial Statements'!H35-'Financial Statements'!G35) | H19: =-('Financial Statements'!I35-'Financial Statements'!H35) | I19: =-('Financial Statements'!J35-'Financial Statements'!I35) | ... Q19: =-('Financial Statements'!R35-'Financial Statements'!Q35)
A20: -Increase in Other Current Assets | B20: =-('Financial Statements'!C36-'Financial Statements'!B36) | C20: =-('Financial Statements'!D36-'Financial Statements'!C36) | D20: =-('Financial Statements'!E36-'Financial Statements'!D36) | E20: =-('Financial Statements'!F36-'Financial Statements'!E36) | F20: =-('Financial Statements'!G36-'Financial Statements'!F36) | G20: =-('Financial Statements'!H36-'Financial Statements'!G36) | H20: =-('Financial Statements'!I36-'Financial Statements'!H36) | I20: =-('Financial Statements'!J36-'Financial Statements'!I36) | ... Q20: =-('Financial Statements'!R36-'Financial Statements'!Q36)
A21: +Increase in Accounts Payable | B21: =('Financial Statements'!C45-'Financial Statements'!B45) | C21: =('Financial Statements'!D45-'Financial Statements'!C45) | D21: =('Financial Statements'!E45-'Financial Statements'!D45) | E21: =('Financial Statements'!F45-'Financial Statements'!E45) | F21: =('Financial Statements'!G45-'Financial Statements'!F45) | G21: =('Financial Statements'!H45-'Financial Statements'!G45) | H21: =('Financial Statements'!I45-'Financial Statements'!H45) | I21: =('Financial Statements'!J45-'Financial Statements'!I45) | ... Q21: =('Financial Statements'!R45-'Financial Statements'!Q45)
A22: +Increase in Taxes Payable | B22: =('Financial Statements'!C46-'Financial Statements'!B46) | C22: =('Financial Statements'!D46-'Financial Statements'!C46) | D22: =('Financial Statements'!E46-'Financial Statements'!D46) | E22: =('Financial Statements'!F46-'Financial Statements'!E46) | F22: =('Financial Statements'!G46-'Financial Statements'!F46) | G22: =('Financial Statements'!H46-'Financial Statements'!G46) | H22: =('Financial Statements'!I46-'Financial Statements'!H46) | I22: =('Financial Statements'!J46-'Financial Statements'!I46) | ... Q22: =('Financial Statements'!R46-'Financial Statements'!Q46)
A23: +Increase in Other Curr. Liabilities | B23: =('Financial Statements'!C47-'Financial Statements'!B47) | C23: =('Financial Statements'!D47-'Financial Statements'!C47) | D23: =('Financial Statements'!E47-'Financial Statements'!D47) | E23: =('Financial Statements'!F47-'Financial Statements'!E47) | F23: =('Financial Statements'!G47-'Financial Statements'!F47) | G23: =('Financial Statements'!H47-'Financial Statements'!G47) | H23: =('Financial Statements'!I47-'Financial Statements'!H47) | I23: =('Financial Statements'!J47-'Financial Statements'!I47) | ... Q23: =('Financial Statements'!R47-'Financial Statements'!Q47)
A24: =Cash From Operations | B24: =B17+B18+B19+B20+B21+B22+B23 | C24: =C17+C18+C19+C20+C21+C22+C23 | D24: =D17+D18+D19+D20+D21+D22+D23 | E24: =E17+E18+E19+E20+E21+E22+E23 | F24: =F17+F18+F19+F20+F21+F22+F23 | G24: =G17+G18+G19+G20+G21+G22+G23 | H24: =H17+H18+H19+H20+H21+H22+H23 | I24: =I17+I18+I19+I20+I21+I22+I23 | ... Q24: =Q17+Q18+Q19+Q20+Q21+Q22+Q23
A26: Investing:
A27: -Capital Expenditures | B27: =-('Financial Statements'!C38-'Financial Statements'!B38-'Financial Statements'!C18) | C27: =-('Financial Statements'!D38-'Financial Statements'!C38-'Financial Statements'!D18) | D27: =-('Financial Statements'!E38-'Financial Statements'!D38-'Financial Statements'!E18) | E27: =-('Financial Statements'!F38-'Financial Statements'!E38-'Financial Statements'!F18) | F27: =-('Financial Statements'!G38-'Financial Statements'!F38-'Financial Statements'!G18) | G27: =-('Financial Statements'!H38-'Financial Statements'!G38-'Financial Statements'!H18) | H27: =-('Financial Statements'!I38-'Financial Statements'!H38-'Financial Statements'!I18) | I27: =-('Financial Statements'!J38-'Financial Statements'!I38-'Financial Statements'!J18) | ... Q27: =-('Financial Statements'!R38-'Financial Statements'!Q38-'Financial Statements'!R18)
A28: -Increase in Investments | B28: =-('Financial Statements'!C39-'Financial Statements'!B39) | C28: =-('Financial Statements'!D39-'Financial Statements'!C39) | D28: =-('Financial Statements'!E39-'Financial Statements'!D39) | E28: =-('Financial Statements'!F39-'Financial Statements'!E39) | F28: =-('Financial Statements'!G39-'Financial Statements'!F39) | G28: =-('Financial Statements'!H39-'Financial Statements'!G39) | H28: =-('Financial Statements'!I39-'Financial Statements'!H39) | I28: =-('Financial Statements'!J39-'Financial Statements'!I39) | ... Q28: =-('Financial Statements'!R39-'Financial Statements'!Q39)
A29: -Purchases of Intangibles | B29: =-('Financial Statements'!C40-'Financial Statements'!B40) | C29: =-('Financial Statements'!D40-'Financial Statements'!C40) | D29: =-('Financial Statements'!E40-'Financial Statements'!D40) | E29: =-('Financial Statements'!F40-'Financial Statements'!E40) | F29: =-('Financial Statements'!G40-'Financial Statements'!F40) | G29: =-('Financial Statements'!H40-'Financial Statements'!G40) | H29: =-('Financial Statements'!I40-'Financial Statements'!H40) | I29: =-('Financial Statements'!J40-'Financial Statements'!I40) | ... Q29: =-('Financial Statements'!R40-'Financial Statements'!Q40)
A30: -Increase in Other Assets | B30: =-('Financial Statements'!C41-'Financial Statements'!B41) | C30: =-('Financial Statements'!D41-'Financial Statements'!C41) | D30: =-('Financial Statements'!E41-'Financial Statements'!D41) | E30: =-('Financial Statements'!F41-'Financial Statements'!E41) | F30: =-('Financial Statements'!G41-'Financial Statements'!F41) | G30: =-('Financial Statements'!H41-'Financial Statements'!G41) | H30: =-('Financial Statements'!I41-'Financial Statements'!H41) | I30: =-('Financial Statements'!J41-'Financial Statements'!I41) | ... Q30: =-('Financial Statements'!R41-'Financial Statements'!Q41)
A31: =Cash From Investing | B31: =B27+B28+B29+B30 | C31: =C27+C28+C29+C30 | D31: =D27+D28+D29+D30 | E31: =E27+E28+E29+E30 | F31: =F27+F28+F29+F30 | G31: =G27+G28+G29+G30 | H31: =H27+H28+H29+H30 | I31: =I27+I28+I29+I30 | ... Q31: =Q27+Q28+Q29+Q30
A33: Financing:
A34: +Increase in Debt | B34: =('Financial Statements'!C44+'Financial Statements'!C49-'Financial Statements'!B44-'Financial Statements'!B49) | C34: =('Financial Statements'!D44+'Financial Statements'!D49-'Financial Statements'!C44-'Financial Statements'!C49) | D34: =('Financial Statements'!E44+'Financial Statements'!E49-'Financial Statements'!D44-'Financial Statements'!D49) | E34: =('Financial Statements'!F44+'Financial Statements'!F49-'Financial Statements'!E44-'Financial Statements'!E49) | F34: =('Financial Statements'!G44+'Financial Statements'!G49-'Financial Statements'!F44-'Financial Statements'!F49) | G34: =('Financial Statements'!H44+'Financial Statements'!H49-'Financial Statements'!G44-'Financial Statements'!G49) | H34: =('Financial Statements'!I44+'Financial Statements'!I49-'Financial Statements'!H44-'Financial Statements'!H49) | I34: =('Financial Statements'!J44+'Financial Statements'!J49-'Financial Statements'!I44-'Financial Statements'!I49) | ... Q34: =('Financial Statements'!R44+'Financial Statements'!R49-'Financial Statements'!Q44-'Financial Statements'!Q49)
A35: -Dividends Paid to Noncontrolling Interest | B35: ='Financial Statements'!C27+'Financial Statements'!C53-'Financial Statements'!B53 | C35: ='Financial Statements'!D27+'Financial Statements'!D53-'Financial Statements'!C53 | D35: ='Financial Statements'!E27+'Financial Statements'!E53-'Financial Statements'!D53 | E35: ='Financial Statements'!F27+'Financial Statements'!F53-'Financial Statements'!E53 | F35: ='Financial Statements'!G27+'Financial Statements'!G53-'Financial Statements'!F53 | G35: ='Financial Statements'!H27+'Financial Statements'!H53-'Financial Statements'!G53 | H35: ='Financial Statements'!I27+'Financial Statements'!I53-'Financial Statements'!H53 | I35: ='Financial Statements'!J27+'Financial Statements'!J53-'Financial Statements'!I53 | ... Q35: ='Financial Statements'!R27+'Financial Statements'!R53-'Financial Statements'!Q53
A36: -Dividends Paid on Preferred | B36: ='Financial Statements'!C28 | C36: ='Financial Statements'!D28 | D36: ='Financial Statements'!E28 | E36: ='Financial Statements'!F28 | F36: ='Financial Statements'!G28 | G36: ='Financial Statements'!H28 | H36: ='Financial Statements'!I28 | I36: ='Financial Statements'!J28 | ... Q36: ='Financial Statements'!R28
A37: +Increase in Pref. Stock | B37: ='Financial Statements'!C54-'Financial Statements'!B54 | C37: ='Financial Statements'!D54-'Financial Statements'!C54 | D37: ='Financial Statements'!E54-'Financial Statements'!D54 | E37: ='Financial Statements'!F54-'Financial Statements'!E54 | F37: ='Financial Statements'!G54-'Financial Statements'!F54 | G37: ='Financial Statements'!H54-'Financial Statements'!G54 | H37: ='Financial Statements'!I54-'Financial Statements'!H54 | I37: ='Financial Statements'!J54-'Financial Statements'!I54 | ... Q37: ='Financial Statements'!R54-'Financial Statements'!Q54
A38: -Dividends Paid on Common | B38: ='Financial Statements'!C64 | C38: ='Financial Statements'!D64 | D38: ='Financial Statements'!E64 | E38: ='Financial Statements'!F64 | F38: ='Financial Statements'!G64 | G38: ='Financial Statements'!H64 | H38: ='Financial Statements'!I64 | I38: ='Financial Statements'!J64 | ... Q38: ='Financial Statements'!R64
A39: +/-Net Issuance of Common Stock | B39: ='Financial Statements'!C55-'Financial Statements'!B55 | C39: ='Financial Statements'!D55-'Financial Statements'!C55 | D39: ='Financial Statements'!E55-'Financial Statements'!D55 | E39: ='Financial Statements'!F55-'Financial Statements'!E55 | F39: ='Financial Statements'!G55-'Financial Statements'!F55 | G39: ='Financial Statements'!H55-'Financial Statements'!G55 | H39: ='Financial Statements'!I55-'Financial Statements'!H55 | I39: ='Financial Statements'!J55-'Financial Statements'!I55 | ... Q39: ='Financial Statements'!R55-'Financial Statements'!Q55
A40: +/-Clean Surplus Plug (Ignore) | B40: ='Financial Statements'!C65 | C40: ='Financial Statements'!D65 | D40: ='Financial Statements'!E65 | E40: ='Financial Statements'!F65 | F40: ='Financial Statements'!G65 | G40: ='Financial Statements'!H65 | H40: ='Financial Statements'!I65 | I40: ='Financial Statements'!J65 | ... Q40: ='Financial Statements'!R65
A41: =Cash From Financing | B41: =SUM(B34:B40) | C41: =SUM(C34:C40) | D41: =SUM(D34:D40) | E41: =SUM(E34:E40) | F41: =SUM(F34:F40) | G41: =SUM(G34:G40) | H41: =SUM(H34:H40) | I41: =SUM(I34:I40) | ... Q41: =SUM(Q34:Q40)
A43: Net Change in Cash | B43: =B24+B31+B41 | C43: =C24+C31+C41 | D43: =D24+D31+D41 | E43: =E24+E31+E41 | F43: =F24+F31+F41 | G43: =G24+G31+G41 | H43: =H24+H31+H41 | I43: =I24+I31+I41 | ... Q43: =Q24+Q31+Q41
A44: + Beginning Cash Balance | B44: ='Financial Statements'!B33 | C44: ='Financial Statements'!C33 | D44: ='Financial Statements'!D33 | E44: ='Financial Statements'!E33 | F44: ='Financial Statements'!F33 | G44: ='Financial Statements'!G33 | H44: ='Financial Statements'!H33 | I44: ='Financial Statements'!I33 | ... Q44: ='Financial Statements'!Q33
A45: = Ending Cash Balance | B45: =B43+B44 | C45: =C43+C44 | D45: =D43+D44 | E45: =E43+E44 | F45: =F43+F44 | G45: =G43+G44 | H45: =H43+H44 | I45: =I43+I44 | ... Q45: =Q43+Q44
A48: Free Cash Flow to Common Equity
A50: Net Income | B50: ='Financial Statements'!C29 | C50: ='Financial Statements'!D29 | D50: ='Financial Statements'!E29 | E50: ='Financial Statements'!F29 | F50: ='Financial Statements'!G29 | G50: ='Financial Statements'!H29 | H50: ='Financial Statements'!I29 | I50: ='Financial Statements'!J29 | ... Q50: ='Financial Statements'!R29
...

Sheet Credit Analysis
A1: Credit Analysis
A4: Company Name | B4: ='Financial Statements'!B4
B6: Actual | C6: Actual | D6: Actual | E6: Actual | F6: Actual | G6: Forecast | H6: Forecast | I6: Forecast | J6: Forecast | K6: Forecast | L6: Forecast | M6: Forecast | N6: Forecast | O6: Forecast | P6: Forecast | Q6: Forecast | R6: Forecast
A7: Fiscal Year End Date | B7: ='Financial Statements'!B8 | C7: ='Financial Statements'!C8 | D7: ='Financial Statements'!D8 | E7: ='Financial Statements'!E8 | F7: ='Financial Statements'!F8 | G7: ='Financial Statements'!G8 | H7: ='Financial Statements'!H8 | I7: ='Financial Statements'!I8 | ... R7: ='Financial Statements'!R8
A9: Analysis of Leverage
A10: - Long-Term Capital Structure
